Workbook

Sheet Formular
B2: Formulation de l'aliment volaille
B3: Type d'aliment | E3: Poulette | H3: Compositions | I3: Norms | J3: Results | K3: Mention
H4: =E3 -> Poulette | L4: EM(kcal/Kg) | M4: Fibres crues (%) | N4: Matières grasses (%) | O4: PB(%) | P4: Lys(%) | Q4: Mét (%) | R4: Mét+Cys (%) | S4: Thr (%) | T4: Trp (%) | U4: Ca (%) | V4: P (%) | W4: Na (%) | X4: Val (%) | Y4: Cl (g/Kg) | Z4: Arg (g/Kg) | AA4: Isl (%) | AB4: K (g/Kg) | AC4: A. Linol (%) | AD4: Vit A (IU/kg) | AE4: Vit B1 (mg/Kg) | AF4: Vit B2 (mg/Kg) | AG4: Vit B6 (mg/Kg) | AH4: Vit B12 (mg/Kg) | AI4: Vit D3 (IU/kg) | AJ4: Vit E (IU/kg) | AK4: Vit K (IU/kg) | AL4: Chol (mg/Kg) | AM4: A. folique (mg/Kg) | AN4: A.nico(mg/Kg) | AO4: A.Panto (mg/Kg) | AP4: Mn (mg/Kg) | AQ4: Zn (mg/Kg) | AR4: Cu (mg/Kg) | AS4: Fer (mg/Kg) | AT4: Iode (mg/Kg) | AU4: Sélénium (mg/Kg) | AV4: Cobalt (mg/Kg)
B5: Matières premières | D5: Taux (%) | E5: Prix/kg | F5: Coût | H5: EM(kcal/Kg) | I5: =INDEX(Base_bromato!$C$68:$L$104,MATCH(Formular!H5,Base_bromato!$B$68:$B$104,0),MATCH(Formular!$E$3,Base_bromato!$C$67:$L$67,0)) -> 2750 | J5: =IF(SUM(OFFSET($L$5,0,ROW()-5,15,1))=0,"",SUM(OFFSET($L$5,0,ROW()-5,15,1))) | L5: =IF($B6="","",$D6/100*VLOOKUP(TRIM($B6),Base_bromato!$A:$AM,3,FALSE)) -> 0 | M5: =IF($B6="","",$D6/100*VLOOKUP(TRIM($B6),Base_bromato!$A:$AM,4,FALSE)) -> 0 | N5: =IF($B6="","",$D6/100*VLOOKUP(TRIM($B6),Base_bromato!$A:$AM,5,FALSE)) -> 0 | O5: =IF($B6="","",$D6/100*VLOOKUP(TRIM($B6),Base_bromato!$A:$AM,6,FALSE)) -> 0 | P5: =IF($B6="","",$D6/100*VLOOKUP(TRIM($B6),Base_bromato!$A:$AM,7,FALSE)) -> 0 | Q5: =IF($B6="","",$D6/100*VLOOKUP(TRIM($B6),Base_bromato!$A:$AM,8,FALSE)) -> 0 | R5: =IF($B6="","",$D6/100*VLOOKUP(TRIM($B6),Base_bromato!$A:$AM,9,FALSE)) -> 0 | S5: =IF($B6="","",$D6/100*VLOOKUP(TRIM($B6),Base_bromato!$A:$AM,10,FALSE)) -> 0 | T5: =IF($B6="","",$D6/100*VLOOKUP(TRIM($B6),Base_bromato!$A:$AM,11,FALSE)) -> 0 | U5: =IF($B6="","",$D6/100*VLOOKUP(TRIM($B6),Base_bromato!$A:$AM,12,FALSE)) -> 0 | V5: =IF($B6="","",$D6/100*VLOOKUP(TRIM($B6),Base_bromato!$A:$AM,13,FALSE)) -> 0 | W5: =IF($B6="","",$D6/100*VLOOKUP(TRIM($B6),Base_bromato!$A:$AM,14,FALSE)) -> 0 | X5: =IF($B6="","",$D6/100*VLOOKUP(TRIM($B6),Base_bromato!$A:$AM,15,FALSE)) -> 0 | Y5: =IF($B6="","",$D6/100*VLOOKUP(TRIM($B6),Base_bromato!$A:$AM,16,FALSE)) -> 0 | Z5: =IF($B6="","",$D6/100*VLOOKUP(TRIM($B6),Base_bromato!$A:$AM,17,FALSE)) -> 0 | AA5: =IF($B6="","",$D6/100*VLOOKUP(TRIM($B6),Base_bromato!$A:$AM,18,FALSE)) -> 0 | AB5: =IF($B6="","",$D6/100*VLOOKUP(TRIM($B6),Base_bromato!$A:$AM,19,FALSE)) -> 0 | AC5: =IF($B6="","",$D6/100*VLOOKUP(TRIM($B6),Base_bromato!$A:$AM,20,FALSE)) -> 0 | AD5: =IF($B6="","",$D6/100*VLOOKUP(TRIM($B6),Base_bromato!$A:$AM,21,FALSE)) -> 0 | AE5: =IF($B6="","",$D6/100*VLOOKUP(TRIM($B6),Base_bromato!$A:$AM,22,FALSE)) -> 0 | AF5: =IF($B6="","",$D6/100*VLOOKUP(TRIM($B6),Base_bromato!$A:$AM,23,FALSE)) -> 0 | AG5: =IF($B6="","",$D6/100*VLOOKUP(TRIM($B6),Base_bromato!$A:$AM,24,FALSE)) -> 0 | AH5: =IF($B6="","",$D6/100*VLOOKUP(TRIM($B6),Base_bromato!$A:$AM,25,FALSE)) -> 0 | AI5: =IF($B6="","",$D6/100*VLOOKUP(TRIM($B6),Base_bromato!$A:$AM,26,FALSE)) -> 0 | AJ5: =IF($B6="","",$D6/100*VLOOKUP(TRIM($B6),Base_bromato!$A:$AM,27,FALSE)) -> 0 | AK5: =IF($B6="","",$D6/100*VLOOKUP(TRIM($B6),Base_bromato!$A:$AM,28,FALSE)) -> 0 | AL5: =IF($B6="","",$D6/100*VLOOKUP(TRIM($B6),Base_bromato!$A:$AM,29,FALSE)) -> 0 | AM5: =IF($B6="","",$D6/100*VLOOKUP(TRIM($B6),Base_bromato!$A:$AM,30,FALSE)) -> 0 | AN5: =IF($B6="","",$D6/100*VLOOKUP(TRIM($B6),Base_bromato!$A:$AM,31,FALSE)) -> 0 | AO5: =IF($B6="","",$D6/100*VLOOKUP(TRIM($B6),Base_bromato!$A:$AM,32,FALSE)) -> 0 | AP5: =IF($B6="","",$D6/100*VLOOKUP(TRIM($B6),Base_bromato!$A:$AM,33,FALSE)) -> 0 | AQ5: =IF($B6="","",$D6/100*VLOOKUP(TRIM($B6),Base_bromato!$A:$AM,34,FALSE)) -> 0 | AR5: =IF($B6="","",$D6/100*VLOOKUP(TRIM($B6),Base_bromato!$A:$AM,35,FALSE)) -> 0 | AS5: =IF($B6="","",$D6/100*VLOOKUP(TRIM($B6),Base_bromato!$A:$AM,36,FALSE)) -> 0 | AT5: =IF($B6="","",$D6/100*VLOOKUP(TRIM($B6),Base_bromato!$A:$AM,37,FALSE)) -> 0 | AU5: =IF($B6="","",$D6/100*VLOOKUP(TRIM($B6),Base_bromato!$A:$AM,38,FALSE)) -> 0 | AV5: =IF($B6="","",$D6/100*VLOOKUP(TRIM($B6),Base_bromato!$A:$AM,39,FALSE)) -> 0
B6: Son de riz | F6: =E6*D6 -> 0 | H6: Fibres crues (%) | I6: =INDEX(Base_bromato!$C$68:$L$104,MATCH(Formular!H6,Base_bromato!$B$68:$B$104,0),MATCH(Formular!$E$3,Base_bromato!$C$67:$L$67,0)) -> 5.5 | J6: =IF(SUM(OFFSET($L$5,0,ROW()-5,15,1))=0,"",SUM(OFFSET($L$5,0,ROW()-5,15,1))) | L6: =IF($B7="","",$D7/100*VLOOKUP(TRIM($B7),Base_bromato!$A:$AM,3,FALSE)) | M6: =IF($B7="","",$D7/100*VLOOKUP(TRIM($B7),Base_bromato!$A:$AM,4,FALSE)) | N6: =IF($B7="","",$D7/100*VLOOKUP(TRIM($B7),Base_bromato!$A:$AM,5,FALSE)) | O6: =IF($B7="","",$D7/100*VLOOKUP(TRIM($B7),Base_bromato!$A:$AM,6,FALSE)) | P6: =IF($B7="","",$D7/100*VLOOKUP(TRIM($B7),Base_bromato!$A:$AM,7,FALSE)) | Q6: =IF($B7="","",$D7/100*VLOOKUP(TRIM($B7),Base_bromato!$A:$AM,8,FALSE)) | R6: =IF($B7="","",$D7/100*VLOOKUP(TRIM($B7),Base_bromato!$A:$AM,9,FALSE)) | S6: =IF($B7="","",$D7/100*VLOOKUP(TRIM($B7),Base_bromato!$A:$AM,10,FALSE)) | T6: =IF($B7="","",$D7/100*VLOOKUP(TRIM($B7),Base_bromato!$A:$AM,11,FALSE)) | U6: =IF($B7="","",$D7/100*VLOOKUP(TRIM($B7),Base_bromato!$A:$AM,12,FALSE)) | V6: =IF($B7="","",$D7/100*VLOOKUP(TRIM($B7),Base_bromato!$A:$AM,13,FALSE)) | W6: =IF($B7="","",$D7/100*VLOOKUP(TRIM($B7),Base_bromato!$A:$AM,14,FALSE)) | X6: =IF($B7="","",$D7/100*VLOOKUP(TRIM($B7),Base_bromato!$A:$AM,15,FALSE)) | Y6: =IF($B7="","",$D7/100*VLOOKUP(TRIM($B7),Base_bromato!$A:$AM,16,FALSE)) | Z6: =IF($B7="","",$D7/100*VLOOKUP(TRIM($B7),Base_bromato!$A:$AM,17,FALSE)) | AA6: =IF($B7="","",$D7/100*VLOOKUP(TRIM($B7),Base_bromato!$A:$AM,18,FALSE)) | AB6: =IF($B7="","",$D7/100*VLOOKUP(TRIM($B7),Base_bromato!$A:$AM,19,FALSE)) | AC6: =IF($B7="","",$D7/100*VLOOKUP(TRIM($B7),Base_bromato!$A:$AM,20,FALSE)) | AD6: =IF($B7="","",$D7/100*VLOOKUP(TRIM($B7),Base_bromato!$A:$AM,21,FALSE)) | AE6: =IF($B7="","",$D7/100*VLOOKUP(TRIM($B7),Base_bromato!$A:$AM,22,FALSE)) | AF6: =IF($B7="","",$D7/100*VLOOKUP(TRIM($B7),Base_bromato!$A:$AM,23,FALSE)) | AG6: =IF($B7="","",$D7/100*VLOOKUP(TRIM($B7),Base_bromato!$A:$AM,24,FALSE)) | AH6: =IF($B7="","",$D7/100*VLOOKUP(TRIM($B7),Base_bromato!$A:$AM,25,FALSE)) | AI6: =IF($B7="","",$D7/100*VLOOKUP(TRIM($B7),Base_bromato!$A:$AM,26,FALSE)) | AJ6: =IF($B7="","",$D7/100*VLOOKUP(TRIM($B7),Base_bromato!$A:$AM,27,FALSE)) | AK6: =IF($B7="","",$D7/100*VLOOKUP(TRIM($B7),Base_bromato!$A:$AM,28,FALSE)) | AL6: =IF($B7="","",$D7/100*VLOOKUP(TRIM($B7),Base_bromato!$A:$AM,29,FALSE)) | AM6: =IF($B7="","",$D7/100*VLOOKUP(TRIM($B7),Base_bromato!$A:$AM,30,FALSE)) | AN6: =IF($B7="","",$D7/100*VLOOKUP(TRIM($B7),Base_bromato!$A:$AM,31,FALSE)) | AO6: =IF($B7="","",$D7/100*VLOOKUP(TRIM($B7),Base_bromato!$A:$AM,32,FALSE)) | AP6: =IF($B7="","",$D7/100*VLOOKUP(TRIM($B7),Base_bromato!$A:$AM,33,FALSE)) | AQ6: =IF($B7="","",$D7/100*VLOOKUP(TRIM($B7),Base_bromato!$A:$AM,34,FALSE)) | AR6: =IF($B7="","",$D7/100*VLOOKUP(TRIM($B7),Base_bromato!$A:$AM,35,FALSE)) | AS6: =IF($B7="","",$D7/100*VLOOKUP(TRIM($B7),Base_bromato!$A:$AM,36,FALSE)) | AT6: =IF($B7="","",$D7/100*VLOOKUP(TRIM($B7),Base_bromato!$A:$AM,37,FALSE)) | AU6: =IF($B7="","",$D7/100*VLOOKUP(TRIM($B7),Base_bromato!$A:$AM,38,FALSE)) | AV6: =IF($B7="","",$D7/100*VLOOKUP(TRIM($B7),Base_bromato!$A:$AM,39,FALSE))
F7: =E7*D7 -> 0 | H7: Matières grasses (%) | I7: =INDEX(Base_bromato!$C$68:$L$104,MATCH(Formular!H7,Base_bromato!$B$68:$B$104,0),MATCH(Formular!$E$3,Base_bromato!$C$67:$L$67,0)) -> 2,5-4 | J7: =IF(SUM(OFFSET($L$5,0,ROW()-5,15,1))=0,"",SUM(OFFSET($L$5,0,ROW()-5,15,1))) | L7: =IF($B8="","",$D8/100*VLOOKUP(TRIM($B8),Base_bromato!$A:$AM,3,FALSE)) | M7: =IF($B8="","",$D8/100*VLOOKUP(TRIM($B8),Base_bromato!$A:$AM,4,FALSE)) | N7: =IF($B8="","",$D8/100*VLOOKUP(TRIM($B8),Base_bromato!$A:$AM,5,FALSE)) | O7: =IF($B8="","",$D8/100*VLOOKUP(TRIM($B8),Base_bromato!$A:$AM,6,FALSE)) | P7: =IF($B8="","",$D8/100*VLOOKUP(TRIM($B8),Base_bromato!$A:$AM,7,FALSE)) | Q7: =IF($B8="","",$D8/100*VLOOKUP(TRIM($B8),Base_bromato!$A:$AM,8,FALSE)) | R7: =IF($B8="","",$D8/100*VLOOKUP(TRIM($B8),Base_bromato!$A:$AM,9,FALSE)) | S7: =IF($B8="","",$D8/100*VLOOKUP(TRIM($B8),Base_bromato!$A:$AM,10,FALSE)) | T7: =IF($B8="","",$D8/100*VLOOKUP(TRIM($B8),Base_bromato!$A:$AM,11,FALSE)) | U7: =IF($B8="","",$D8/100*VLOOKUP(TRIM($B8),Base_bromato!$A:$AM,12,FALSE)) | V7: =IF($B8="","",$D8/100*VLOOKUP(TRIM($B8),Base_bromato!$A:$AM,13,FALSE)) | W7: =IF($B8="","",$D8/100*VLOOKUP(TRIM($B8),Base_bromato!$A:$AM,14,FALSE)) | X7: =IF($B8="","",$D8/100*VLOOKUP(TRIM($B8),Base_bromato!$A:$AM,15,FALSE)) | Y7: =IF($B8="","",$D8/100*VLOOKUP(TRIM($B8),Base_bromato!$A:$AM,16,FALSE)) | Z7: =IF($B8="","",$D8/100*VLOOKUP(TRIM($B8),Base_bromato!$A:$AM,17,FALSE)) | AA7: =IF($B8="","",$D8/100*VLOOKUP(TRIM($B8),Base_bromato!$A:$AM,18,FALSE)) | AB7: =IF($B8="","",$D8/100*VLOOKUP(TRIM($B8),Base_bromato!$A:$AM,19,FALSE)) | AC7: =IF($B8="","",$D8/100*VLOOKUP(TRIM($B8),Base_bromato!$A:$AM,20,FALSE)) | AD7: =IF($B8="","",$D8/100*VLOOKUP(TRIM($B8),Base_bromato!$A:$AM,21,FALSE)) | AE7: =IF($B8="","",$D8/100*VLOOKUP(TRIM($B8),Base_bromato!$A:$AM,22,FALSE)) | AF7: =IF($B8="","",$D8/100*VLOOKUP(TRIM($B8),Base_bromato!$A:$AM,23,FALSE)) | AG7: =IF($B8="","",$D8/100*VLOOKUP(TRIM($B8),Base_bromato!$A:$AM,24,FALSE)) | AH7: =IF($B8="","",$D8/100*VLOOKUP(TRIM($B8),Base_bromato!$A:$AM,25,FALSE)) | AI7: =IF($B8="","",$D8/100*VLOOKUP(TRIM($B8),Base_bromato!$A:$AM,26,FALSE)) | AJ7: =IF($B8="","",$D8/100*VLOOKUP(TRIM($B8),Base_bromato!$A:$AM,27,FALSE)) | AK7: =IF($B8="","",$D8/100*VLOOKUP(TRIM($B8),Base_bromato!$A:$AM,28,FALSE)) | AL7: =IF($B8="","",$D8/100*VLOOKUP(TRIM($B8),Base_bromato!$A:$AM,29,FALSE)) | AM7: =IF($B8="","",$D8/100*VLOOKUP(TRIM($B8),Base_bromato!$A:$AM,30,FALSE)) | AN7: =IF($B8="","",$D8/100*VLOOKUP(TRIM($B8),Base_bromato!$A:$AM,31,FALSE)) | AO7: =IF($B8="","",$D8/100*VLOOKUP(TRIM($B8),Base_bromato!$A:$AM,32,FALSE)) | AP7: =IF($B8="","",$D8/100*VLOOKUP(TRIM($B8),Base_bromato!$A:$AM,33,FALSE)) | AQ7: =IF($B8="","",$D8/100*VLOOKUP(TRIM($B8),Base_bromato!$A:$AM,34,FALSE)) | AR7: =IF($B8="","",$D8/100*VLOOKUP(TRIM($B8),Base_bromato!$A:$AM,35,FALSE)) | AS7: =IF($B8="","",$D8/100*VLOOKUP(TRIM($B8),Base_bromato!$A:$AM,36,FALSE)) | AT7: =IF($B8="","",$D8/100*VLOOKUP(TRIM($B8),Base_bromato!$A:$AM,37,FALSE)) | AU7: =IF($B8="","",$D8/100*VLOOKUP(TRIM($B8),Base_bromato!$A:$AM,38,FALSE)) | AV7: =IF($B8="","",$D8/100*VLOOKUP(TRIM($B8),Base_bromato!$A:$AM,39,FALSE))
F8: =E8*D8 -> 0 | H8: PB(%) | I8: =INDEX(Base_bromato!$C$68:$L$104,MATCH(Formular!H8,Base_bromato!$B$68:$B$104,0),MATCH(Formular!$E$3,Base_bromato!$C$67:$L$67,0)) -> 16 | J8: =IF(SUM(OFFSET($L$5,0,ROW()-5,15,1))=0,"",SUM(OFFSET($L$5,0,ROW()-5,15,1))) | L8: =IF($B9="","",$D9/100*VLOOKUP(TRIM($B9),Base_bromato!$A:$AM,3,FALSE)) | M8: =IF($B9="","",$D9/100*VLOOKUP(TRIM($B9),Base_bromato!$A:$AM,4,FALSE)) | N8: =IF($B9="","",$D9/100*VLOOKUP(TRIM($B9),Base_bromato!$A:$AM,5,FALSE)) | O8: =IF($B9="","",$D9/100*VLOOKUP(TRIM($B9),Base_bromato!$A:$AM,6,FALSE)) | P8: =IF($B9="","",$D9/100*VLOOKUP(TRIM($B9),Base_bromato!$A:$AM,7,FALSE)) | Q8: =IF($B9="","",$D9/100*VLOOKUP(TRIM($B9),Base_bromato!$A:$AM,8,FALSE)) | R8: =IF($B9="","",$D9/100*VLOOKUP(TRIM($B9),Base_bromato!$A:$AM,9,FALSE)) | S8: =IF($B9="","",$D9/100*VLOOKUP(TRIM($B9),Base_bromato!$A:$AM,10,FALSE)) | T8: =IF($B9="","",$D9/100*VLOOKUP(TRIM($B9),Base_bromato!$A:$AM,11,FALSE)) | U8: =IF($B9="","",$D9/100*VLOOKUP(TRIM($B9),Base_bromato!$A:$AM,12,FALSE)) | V8: =IF($B9="","",$D9/100*VLOOKUP(TRIM($B9),Base_bromato!$A:$AM,13,FALSE)) | W8: =IF($B9="","",$D9/100*VLOOKUP(TRIM($B9),Base_bromato!$A:$AM,14,FALSE)) | X8: =IF($B9="","",$D9/100*VLOOKUP(TRIM($B9),Base_bromato!$A:$AM,15,FALSE)) | Y8: =IF($B9="","",$D9/100*VLOOKUP(TRIM($B9),Base_bromato!$A:$AM,16,FALSE)) | Z8: =IF($B9="","",$D9/100*VLOOKUP(TRIM($B9),Base_bromato!$A:$AM,17,FALSE)) | AA8: =IF($B9="","",$D9/100*VLOOKUP(TRIM($B9),Base_bromato!$A:$AM,18,FALSE)) | AB8: =IF($B9="","",$D9/100*VLOOKUP(TRIM($B9),Base_bromato!$A:$AM,19,FALSE)) | AC8: =IF($B9="","",$D9/100*VLOOKUP(TRIM($B9),Base_bromato!$A:$AM,20,FALSE)) | AD8: =IF($B9="","",$D9/100*VLOOKUP(TRIM($B9),Base_bromato!$A:$AM,21,FALSE)) | AE8: =IF($B9="","",$D9/100*VLOOKUP(TRIM($B9),Base_bromato!$A:$AM,22,FALSE)) | AF8: =IF($B9="","",$D9/100*VLOOKUP(TRIM($B9),Base_bromato!$A:$AM,23,FALSE)) | AG8: =IF($B9="","",$D9/100*VLOOKUP(TRIM($B9),Base_bromato!$A:$AM,24,FALSE)) | AH8: =IF($B9="","",$D9/100*VLOOKUP(TRIM($B9),Base_bromato!$A:$AM,25,FALSE)) | AI8: =IF($B9="","",$D9/100*VLOOKUP(TRIM($B9),Base_bromato!$A:$AM,26,FALSE)) | AJ8: =IF($B9="","",$D9/100*VLOOKUP(TRIM($B9),Base_bromato!$A:$AM,27,FALSE)) | AK8: =IF($B9="","",$D9/100*VLOOKUP(TRIM($B9),Base_bromato!$A:$AM,28,FALSE)) | AL8: =IF($B9="","",$D9/100*VLOOKUP(TRIM($B9),Base_bromato!$A:$AM,29,FALSE)) | AM8: =IF($B9="","",$D9/100*VLOOKUP(TRIM($B9),Base_bromato!$A:$AM,30,FALSE)) | AN8: =IF($B9="","",$D9/100*VLOOKUP(TRIM($B9),Base_bromato!$A:$AM,31,FALSE)) | AO8: =IF($B9="","",$D9/100*VLOOKUP(TRIM($B9),Base_bromato!$A:$AM,32,FALSE)) | AP8: =IF($B9="","",$D9/100*VLOOKUP(TRIM($B9),Base_bromato!$A:$AM,33,FALSE)) | AQ8: =IF($B9="","",$D9/100*VLOOKUP(TRIM($B9),Base_bromato!$A:$AM,34,FALSE)) | AR8: =IF($B9="","",$D9/100*VLOOKUP(TRIM($B9),Base_bromato!$A:$AM,35,FALSE)) | AS8: =IF($B9="","",$D9/100*VLOOKUP(TRIM($B9),Base_bromato!$A:$AM,36,FALSE)) | AT8: =IF($B9="","",$D9/100*VLOOKUP(TRIM($B9),Base_bromato!$A:$AM,37,FALSE)) | AU8: =IF($B9="","",$D9/100*VLOOKUP(TRIM($B9),Base_bromato!$A:$AM,38,FALSE)) | AV8: =IF($B9="","",$D9/100*VLOOKUP(TRIM($B9),Base_bromato!$A:$AM,39,FALSE))
F9: =E9*D9 -> 0 | H9: Lys(%) | I9: =INDEX(Base_bromato!$C$68:$L$104,MATCH(Formular!H9,Base_bromato!$B$68:$B$104,0),MATCH(Formular!$E$3,Base_bromato!$C$67:$L$67,0)) -> 0,74-0,78 | J9: =IF(SUM(OFFSET($L$5,0,ROW()-5,15,1))=0,"",SUM(OFFSET($L$5,0,ROW()-5,15,1))) | L9: =IF($B10="","",$D10/100*VLOOKUP(TRIM($B10),Base_bromato!$A:$AM,3,FALSE)) | M9: =IF($B10="","",$D10/100*VLOOKUP(TRIM($B10),Base_bromato!$A:$AM,4,FALSE)) | N9: =IF($B10="","",$D10/100*VLOOKUP(TRIM($B10),Base_bromato!$A:$AM,5,FALSE)) | O9: =IF($B10="","",$D10/100*VLOOKUP(TRIM($B10),Base_bromato!$A:$AM,6,FALSE)) | P9: =IF($B10="","",$D10/100*VLOOKUP(TRIM($B10),Base_bromato!$A:$AM,7,FALSE)) | Q9: =IF($B10="","",$D10/100*VLOOKUP(TRIM($B10),Base_bromato!$A:$AM,8,FALSE)) | R9: =IF($B10="","",$D10/100*VLOOKUP(TRIM($B10),Base_bromato!$A:$AM,9,FALSE)) | S9: =IF($B10="","",$D10/100*VLOOKUP(TRIM($B10),Base_bromato!$A:$AM,10,FALSE)) | T9: =IF($B10="","",$D10/100*VLOOKUP(TRIM($B10),Base_bromato!$A:$AM,11,FALSE)) | U9: =IF($B10="","",$D10/100*VLOOKUP(TRIM($B10),Base_bromato!$A:$AM,12,FALSE)) | V9: =IF($B10="","",$D10/100*VLOOKUP(TRIM($B10),Base_bromato!$A:$AM,13,FALSE)) | W9: =IF($B10="","",$D10/100*VLOOKUP(TRIM($B10),Base_bromato!$A:$AM,14,FALSE)) | X9: =IF($B10="","",$D10/100*VLOOKUP(TRIM($B10),Base_bromato!$A:$AM,15,FALSE)) | Y9: =IF($B10="","",$D10/100*VLOOKUP(TRIM($B10),Base_bromato!$A:$AM,16,FALSE)) | Z9: =IF($B10="","",$D10/100*VLOOKUP(TRIM($B10),Base_bromato!$A:$AM,17,FALSE)) | AA9: =IF($B10="","",$D10/100*VLOOKUP(TRIM($B10),Base_bromato!$A:$AM,18,FALSE)) | AB9: =IF($B10="","",$D10/100*VLOOKUP(TRIM($B10),Base_bromato!$A:$AM,19,FALSE)) | AC9: =IF($B10="","",$D10/100*VLOOKUP(TRIM($B10),Base_bromato!$A:$AM,20,FALSE)) | AD9: =IF($B10="","",$D10/100*VLOOKUP(TRIM($B10),Base_bromato!$A:$AM,21,FALSE)) | AE9: =IF($B10="","",$D10/100*VLOOKUP(TRIM($B10),Base_bromato!$A:$AM,22,FALSE)) | AF9: =IF($B10="","",$D10/100*VLOOKUP(TRIM($B10),Base_bromato!$A:$AM,23,FALSE)) | AG9: =IF($B10="","",$D10/100*VLOOKUP(TRIM($B10),Base_bromato!$A:$AM,24,FALSE)) | AH9: =IF($B10="","",$D10/100*VLOOKUP(TRIM($B10),Base_bromato!$A:$AM,25,FALSE)) | AI9: =IF($B10="","",$D10/100*VLOOKUP(TRIM($B10),Base_bromato!$A:$AM,26,FALSE)) | AJ9: =IF($B10="","",$D10/100*VLOOKUP(TRIM($B10),Base_bromato!$A:$AM,27,FALSE)) | AK9: =IF($B10="","",$D10/100*VLOOKUP(TRIM($B10),Base_bromato!$A:$AM,28,FALSE)) | AL9: =IF($B10="","",$D10/100*VLOOKUP(TRIM($B10),Base_bromato!$A:$AM,29,FALSE)) | AM9: =IF($B10="","",$D10/100*VLOOKUP(TRIM($B10),Base_bromato!$A:$AM,30,FALSE)) | AN9: =IF($B10="","",$D10/100*VLOOKUP(TRIM($B10),Base_bromato!$A:$AM,31,FALSE)) | AO9: =IF($B10="","",$D10/100*VLOOKUP(TRIM($B10),Base_bromato!$A:$AM,32,FALSE)) | AP9: =IF($B10="","",$D10/100*VLOOKUP(TRIM($B10),Base_bromato!$A:$AM,33,FALSE)) | AQ9: =IF($B10="","",$D10/100*VLOOKUP(TRIM($B10),Base_bromato!$A:$AM,34,FALSE)) | AR9: =IF($B10="","",$D10/100*VLOOKUP(TRIM($B10),Base_bromato!$A:$AM,35,FALSE)) | AS9: =IF($B10="","",$D10/100*VLOOKUP(TRIM($B10),Base_bromato!$A:$AM,36,FALSE)) | AT9: =IF($B10="","",$D10/100*VLOOKUP(TRIM($B10),Base_bromato!$A:$AM,37,FALSE)) | AU9: =IF($B10="","",$D10/100*VLOOKUP(TRIM($B10),Base_bromato!$A:$AM,38,FALSE)) | AV9: =IF($B10="","",$D10/100*VLOOKUP(TRIM($B10),Base_bromato!$A:$AM,39,FALSE))
F10: =E10*D10 -> 0 | H10: Mét (%) | I10: =INDEX(Base_bromato!$C$68:$L$104,MATCH(Formular!H10,Base_bromato!$B$68:$B$104,0),MATCH(Formular!$E$3,Base_bromato!$C$67:$L$67,0)) -> 0,33-0,35 | J10: =IF(SUM(OFFSET($L$5,0,ROW()-5,15,1))=0,"",SUM(OFFSET($L$5,0,ROW()-5,15,1))) | L10: =IF($B11="","",$D11/100*VLOOKUP(TRIM($B11),Base_bromato!$A:$AM,3,FALSE)) | M10: =IF($B11="","",$D11/100*VLOOKUP(TRIM($B11),Base_bromato!$A:$AM,4,FALSE)) | N10: =IF($B11="","",$D11/100*VLOOKUP(TRIM($B11),Base_bromato!$A:$AM,5,FALSE)) | O10: =IF($B11="","",$D11/100*VLOOKUP(TRIM($B11),Base_bromato!$A:$AM,6,FALSE)) | P10: =IF($B11="","",$D11/100*VLOOKUP(TRIM($B11),Base_bromato!$A:$AM,7,FALSE)) | Q10: =IF($B11="","",$D11/100*VLOOKUP(TRIM($B11),Base_bromato!$A:$AM,8,FALSE)) | R10: =IF($B11="","",$D11/100*VLOOKUP(TRIM($B11),Base_bromato!$A:$AM,9,FALSE)) | S10: =IF($B11="","",$D11/100*VLOOKUP(TRIM($B11),Base_bromato!$A:$AM,10,FALSE)) | T10: =IF($B11="","",$D11/100*VLOOKUP(TRIM($B11),Base_bromato!$A:$AM,11,FALSE)) | U10: =IF($B11="","",$D11/100*VLOOKUP(TRIM($B11),Base_bromato!$A:$AM,12,FALSE)) | V10: =IF($B11="","",$D11/100*VLOOKUP(TRIM($B11),Base_bromato!$A:$AM,13,FALSE)) | W10: =IF($B11="","",$D11/100*VLOOKUP(TRIM($B11),Base_bromato!$A:$AM,14,FALSE)) | X10: =IF($B11="","",$D11/100*VLOOKUP(TRIM($B11),Base_bromato!$A:$AM,15,FALSE)) | Y10: =IF($B11="","",$D11/100*VLOOKUP(TRIM($B11),Base_bromato!$A:$AM,16,FALSE)) | Z10: =IF($B11="","",$D11/100*VLOOKUP(TRIM($B11),Base_bromato!$A:$AM,17,FALSE)) | AA10: =IF($B11="","",$D11/100*VLOOKUP(TRIM($B11),Base_bromato!$A:$AM,18,FALSE)) | AB10: =IF($B11="","",$D11/100*VLOOKUP(TRIM($B11),Base_bromato!$A:$AM,19,FALSE)) | AC10: =IF($B11="","",$D11/100*VLOOKUP(TRIM($B11),Base_bromato!$A:$AM,20,FALSE)) | AD10: =IF($B11="","",$D11/100*VLOOKUP(TRIM($B11),Base_bromato!$A:$AM,21,FALSE)) | AE10: =IF($B11="","",$D11/100*VLOOKUP(TRIM($B11),Base_bromato!$A:$AM,22,FALSE)) | AF10: =IF($B11="","",$D11/100*VLOOKUP(TRIM($B11),Base_bromato!$A:$AM,23,FALSE)) | AG10: =IF($B11="","",$D11/100*VLOOKUP(TRIM($B11),Base_bromato!$A:$AM,24,FALSE)) | AH10: =IF($B11="","",$D11/100*VLOOKUP(TRIM($B11),Base_bromato!$A:$AM,25,FALSE)) | AI10: =IF($B11="","",$D11/100*VLOOKUP(TRIM($B11),Base_bromato!$A:$AM,26,FALSE)) | AJ10: =IF($B11="","",$D11/100*VLOOKUP(TRIM($B11),Base_bromato!$A:$AM,27,FALSE)) | AK10: =IF($B11="","",$D11/100*VLOOKUP(TRIM($B11),Base_bromato!$A:$AM,28,FALSE)) | AL10: =IF($B11="","",$D11/100*VLOOKUP(TRIM($B11),Base_bromato!$A:$AM,29,FALSE)) | AM10: =IF($B11="","",$D11/100*VLOOKUP(TRIM($B11),Base_bromato!$A:$AM,30,FALSE)) | AN10: =IF($B11="","",$D11/100*VLOOKUP(TRIM($B11),Base_bromato!$A:$AM,31,FALSE)) | AO10: =IF($B11="","",$D11/100*VLOOKUP(TRIM($B11),Base_bromato!$A:$AM,32,FALSE)) | AP10: =IF($B11="","",$D11/100*VLOOKUP(TRIM($B11),Base_bromato!$A:$AM,33,FALSE)) | AQ10: =IF($B11="","",$D11/100*VLOOKUP(TRIM($B11),Base_bromato!$A:$AM,34,FALSE)) | AR10: =IF($B11="","",$D11/100*VLOOKUP(TRIM($B11),Base_bromato!$A:$AM,35,FALSE)) | AS10: =IF($B11="","",$D11/100*VLOOKUP(TRIM($B11),Base_bromato!$A:$AM,36,FALSE)) | AT10: =IF($B11="","",$D11/100*VLOOKUP(TRIM($B11),Base_bromato!$A:$AM,37,FALSE)) | AU10: =IF($B11="","",$D11/100*VLOOKUP(TRIM($B11),Base_bromato!$A:$AM,38,FALSE)) | AV10: =IF($B11="","",$D11/100*VLOOKUP(TRIM($B11),Base_bromato!$A:$AM,39,FALSE))
F11: =E11*D11 -> 0 | H11: Mét+Cys (%) | I11: =INDEX(Base_bromato!$C$68:$L$104,MATCH(Formular!H11,Base_bromato!$B$68:$B$104,0),MATCH(Formular!$E$3,Base_bromato!$C$67:$L$67,0)) -> 0,60-0,63 | J11: =IF(SUM(OFFSET($L$5,0,ROW()-5,15,1))=0,"",SUM(OFFSET($L$5,0,ROW()-5,15,1))) | L11: =IF($B12="","",$D12/100*VLOOKUP(TRIM($B12),Base_bromato!$A:$AM,3,FALSE)) | M11: =IF($B12="","",$D12/100*VLOOKUP(TRIM($B12),Base_bromato!$A:$AM,4,FALSE)) | N11: =IF($B12="","",$D12/100*VLOOKUP(TRIM($B12),Base_bromato!$A:$AM,5,FALSE)) | O11: =IF($B12="","",$D12/100*VLOOKUP(TRIM($B12),Base_bromato!$A:$AM,6,FALSE)) | P11: =IF($B12="","",$D12/100*VLOOKUP(TRIM($B12),Base_bromato!$A:$AM,7,FALSE)) | Q11: =IF($B12="","",$D12/100*VLOOKUP(TRIM($B12),Base_bromato!$A:$AM,8,FALSE)) | R11: =IF($B12="","",$D12/100*VLOOKUP(TRIM($B12),Base_bromato!$A:$AM,9,FALSE)) | S11: =IF($B12="","",$D12/100*VLOOKUP(TRIM($B12),Base_bromato!$A:$AM,10,FALSE)) | T11: =IF($B12="","",$D12/100*VLOOKUP(TRIM($B12),Base_bromato!$A:$AM,11,FALSE)) | U11: =IF($B12="","",$D12/100*VLOOKUP(TRIM($B12),Base_bromato!$A:$AM,12,FALSE)) | V11: =IF($B12="","",$D12/100*VLOOKUP(TRIM($B12),Base_bromato!$A:$AM,13,FALSE)) | W11: =IF($B12="","",$D12/100*VLOOKUP(TRIM($B12),Base_bromato!$A:$AM,14,FALSE)) | X11: =IF($B12="","",$D12/100*VLOOKUP(TRIM($B12),Base_bromato!$A:$AM,15,FALSE)) | Y11: =IF($B12="","",$D12/100*VLOOKUP(TRIM($B12),Base_bromato!$A:$AM,16,FALSE)) | Z11: =IF($B12="","",$D12/100*VLOOKUP(TRIM($B12),Base_bromato!$A:$AM,17,FALSE)) | AA11: =IF($B12="","",$D12/100*VLOOKUP(TRIM($B12),Base_bromato!$A:$AM,18,FALSE)) | AB11: =IF($B12="","",$D12/100*VLOOKUP(TRIM($B12),Base_bromato!$A:$AM,19,FALSE)) | AC11: =IF($B12="","",$D12/100*VLOOKUP(TRIM($B12),Base_bromato!$A:$AM,20,FALSE)) | AD11: =IF($B12="","",$D12/100*VLOOKUP(TRIM($B12),Base_bromato!$A:$AM,21,FALSE)) | AE11: =IF($B12="","",$D12/100*VLOOKUP(TRIM($B12),Base_bromato!$A:$AM,22,FALSE)) | AF11: =IF($B12="","",$D12/100*VLOOKUP(TRIM($B12),Base_bromato!$A:$AM,23,FALSE)) | AG11: =IF($B12="","",$D12/100*VLOOKUP(TRIM($B12),Base_bromato!$A:$AM,24,FALSE)) | AH11: =IF($B12="","",$D12/100*VLOOKUP(TRIM($B12),Base_bromato!$A:$AM,25,FALSE)) | AI11: =IF($B12="","",$D12/100*VLOOKUP(TRIM($B12),Base_bromato!$A:$AM,26,FALSE)) | AJ11: =IF($B12="","",$D12/100*VLOOKUP(TRIM($B12),Base_bromato!$A:$AM,27,FALSE)) | AK11: =IF($B12="","",$D12/100*VLOOKUP(TRIM($B12),Base_bromato!$A:$AM,28,FALSE)) | AL11: =IF($B12="","",$D12/100*VLOOKUP(TRIM($B12),Base_bromato!$A:$AM,29,FALSE)) | AM11: =IF($B12="","",$D12/100*VLOOKUP(TRIM($B12),Base_bromato!$A:$AM,30,FALSE)) | AN11: =IF($B12="","",$D12/100*VLOOKUP(TRIM($B12),Base_bromato!$A:$AM,31,FALSE)) | AO11: =IF($B12="","",$D12/100*VLOOKUP(TRIM($B12),Base_bromato!$A:$AM,32,FALSE)) | AP11: =IF($B12="","",$D12/100*VLOOKUP(TRIM($B12),Base_bromato!$A:$AM,33,FALSE)) | AQ11: =IF($B12="","",$D12/100*VLOOKUP(TRIM($B12),Base_bromato!$A:$AM,34,FALSE)) | AR11: =IF($B12="","",$D12/100*VLOOKUP(TRIM($B12),Base_bromato!$A:$AM,35,FALSE)) | AS11: =IF($B12="","",$D12/100*VLOOKUP(TRIM($B12),Base_bromato!$A:$AM,36,FALSE)) | AT11: =IF($B12="","",$D12/100*VLOOKUP(TRIM($B12),Base_bromato!$A:$AM,37,FALSE)) | AU11: =IF($B12="","",$D12/100*VLOOKUP(TRIM($B12),Base_bromato!$A:$AM,38,FALSE)) | AV11: =IF($B12="","",$D12/100*VLOOKUP(TRIM($B12),Base_bromato!$A:$AM,39,FALSE))
F12: =E12*D12 -> 0 | H12: Thr (%) | I12: =INDEX(Base_bromato!$C$68:$L$104,MATCH(Formular!H12,Base_bromato!$B$68:$B$104,0),MATCH(Formular!$E$3,Base_bromato!$C$67:$L$67,0)) -> 0,50-0,53 | J12: =IF(SUM(OFFSET($L$5,0,ROW()-5,15,1))=0,"",SUM(OFFSET($L$5,0,ROW()-5,15,1))) | L12: =IF($B13="","",$D13/100*VLOOKUP(TRIM($B13),Base_bromato!$A:$AM,3,FALSE)) | M12: =IF($B13="","",$D13/100*VLOOKUP(TRIM($B13),Base_bromato!$A:$AM,4,FALSE)) | N12: =IF($B13="","",$D13/100*VLOOKUP(TRIM($B13),Base_bromato!$A:$AM,5,FALSE)) | O12: =IF($B13="","",$D13/100*VLOOKUP(TRIM($B13),Base_bromato!$A:$AM,6,FALSE)) | P12: =IF($B13="","",$D13/100*VLOOKUP(TRIM($B13),Base_bromato!$A:$AM,7,FALSE)) | Q12: =IF($B13="","",$D13/100*VLOOKUP(TRIM($B13),Base_bromato!$A:$AM,8,FALSE)) | R12: =IF($B13="","",$D13/100*VLOOKUP(TRIM($B13),Base_bromato!$A:$AM,9,FALSE)) | S12: =IF($B13="","",$D13/100*VLOOKUP(TRIM($B13),Base_bromato!$A:$AM,10,FALSE)) | T12: =IF($B13="","",$D13/100*VLOOKUP(TRIM($B13),Base_bromato!$A:$AM,11,FALSE)) | U12: =IF($B13="","",$D13/100*VLOOKUP(TRIM($B13),Base_bromato!$A:$AM,12,FALSE)) | V12: =IF($B13="","",$D13/100*VLOOKUP(TRIM($B13),Base_bromato!$A:$AM,13,FALSE)) | W12: =IF($B13="","",$D13/100*VLOOKUP(TRIM($B13),Base_bromato!$A:$AM,14,FALSE)) | X12: =IF($B13="","",$D13/100*VLOOKUP(TRIM($B13),Base_bromato!$A:$AM,15,FALSE)) | Y12: =IF($B13="","",$D13/100*VLOOKUP(TRIM($B13),Base_bromato!$A:$AM,16,FALSE)) | Z12: =IF($B13="","",$D13/100*VLOOKUP(TRIM($B13),Base_bromato!$A:$AM,17,FALSE)) | AA12: =IF($B13="","",$D13/100*VLOOKUP(TRIM($B13),Base_bromato!$A:$AM,18,FALSE)) | AB12: =IF($B13="","",$D13/100*VLOOKUP(TRIM($B13),Base_bromato!$A:$AM,19,FALSE)) | AC12: =IF($B13="","",$D13/100*VLOOKUP(TRIM($B13),Base_bromato!$A:$AM,20,FALSE)) | AD12: =IF($B13="","",$D13/100*VLOOKUP(TRIM($B13),Base_bromato!$A:$AM,21,FALSE)) | AE12: =IF($B13="","",$D13/100*VLOOKUP(TRIM($B13),Base_bromato!$A:$AM,22,FALSE)) | AF12: =IF($B13="","",$D13/100*VLOOKUP(TRIM($B13),Base_bromato!$A:$AM,23,FALSE)) | AG12: =IF($B13="","",$D13/100*VLOOKUP(TRIM($B13),Base_bromato!$A:$AM,24,FALSE)) | AH12: =IF($B13="","",$D13/100*VLOOKUP(TRIM($B13),Base_bromato!$A:$AM,25,FALSE)) | AI12: =IF($B13="","",$D13/100*VLOOKUP(TRIM($B13),Base_bromato!$A:$AM,26,FALSE)) | AJ12: =IF($B13="","",$D13/100*VLOOKUP(TRIM($B13),Base_bromato!$A:$AM,27,FALSE)) | AK12: =IF($B13="","",$D13/100*VLOOKUP(TRIM($B13),Base_bromato!$A:$AM,28,FALSE)) | AL12: =IF($B13="","",$D13/100*VLOOKUP(TRIM($B13),Base_bromato!$A:$AM,29,FALSE)) | AM12: =IF($B13="","",$D13/100*VLOOKUP(TRIM($B13),Base_bromato!$A:$AM,30,FALSE)) | AN12: =IF($B13="","",$D13/100*VLOOKUP(TRIM($B13),Base_bromato!$A:$AM,31,FALSE)) | AO12: =IF($B13="","",$D13/100*VLOOKUP(TRIM($B13),Base_bromato!$A:$AM,32,FALSE)) | AP12: =IF($B13="","",$D13/100*VLOOKUP(TRIM($B13),Base_bromato!$A:$AM,33,FALSE)) | AQ12: =IF($B13="","",$D13/100*VLOOKUP(TRIM($B13),Base_bromato!$A:$AM,34,FALSE)) | AR12: =IF($B13="","",$D13/100*VLOOKUP(TRIM($B13),Base_bromato!$A:$AM,35,FALSE)) | AS12: =IF($B13="","",$D13/100*VLOOKUP(TRIM($B13),Base_bromato!$A:$AM,36,FALSE)) | AT12: =IF($B13="","",$D13/100*VLOOKUP(TRIM($B13),Base_bromato!$A:$AM,37,FALSE)) | AU12: =IF($B13="","",$D13/100*VLOOKUP(TRIM($B13),Base_bromato!$A:$AM,38,FALSE)) | AV12: =IF($B13="","",$D13/100*VLOOKUP(TRIM($B13),Base_bromato!$A:$AM,39,FALSE))
F13: =E13*D13 -> 0 | H13: Trp (%) | I13: =INDEX(Base_bromato!$C$68:$L$104,MATCH(Formular!H13,Base_bromato!$B$68:$B$104,0),MATCH(Formular!$E$3,Base_bromato!$C$67:$L$67,0)) -> 0,168-0,175 | J13: =IF(SUM(OFFSET($L$5,0,ROW()-5,15,1))=0,"",SUM(OFFSET($L$5,0,ROW()-5,15,1))) | L13: =IF($B14="","",$D14/100*VLOOKUP(TRIM($B14),Base_bromato!$A:$AM,3,FALSE)) | M13: =IF($B14="","",$D14/100*VLOOKUP(TRIM($B14),Base_bromato!$A:$AM,4,FALSE)) | N13: =IF($B14="","",$D14/100*VLOOKUP(TRIM($B14),Base_bromato!$A:$AM,5,FALSE)) | O13: =IF($B14="","",$D14/100*VLOOKUP(TRIM($B14),Base_bromato!$A:$AM,6,FALSE)) | P13: =IF($B14="","",$D14/100*VLOOKUP(TRIM($B14),Base_bromato!$A:$AM,7,FALSE)) | Q13: =IF($B14="","",$D14/100*VLOOKUP(TRIM($B14),Base_bromato!$A:$AM,8,FALSE)) | R13: =IF($B14="","",$D14/100*VLOOKUP(TRIM($B14),Base_bromato!$A:$AM,9,FALSE)) | S13: =IF($B14="","",$D14/100*VLOOKUP(TRIM($B14),Base_bromato!$A:$AM,10,FALSE)) | T13: =IF($B14="","",$D14/100*VLOOKUP(TRIM($B14),Base_bromato!$A:$AM,11,FALSE)) | U13: =IF($B14="","",$D14/100*VLOOKUP(TRIM($B14),Base_bromato!$A:$AM,12,FALSE)) | V13: =IF($B14="","",$D14/100*VLOOKUP(TRIM($B14),Base_bromato!$A:$AM,13,FALSE)) | W13: =IF($B14="","",$D14/100*VLOOKUP(TRIM($B14),Base_bromato!$A:$AM,14,FALSE)) | X13: =IF($B14="","",$D14/100*VLOOKUP(TRIM($B14),Base_bromato!$A:$AM,15,FALSE)) | Y13: =IF($B14="","",$D14/100*VLOOKUP(TRIM($B14),Base_bromato!$A:$AM,16,FALSE)) | Z13: =IF($B14="","",$D14/100*VLOOKUP(TRIM($B14),Base_bromato!$A:$AM,17,FALSE)) | AA13: =IF($B14="","",$D14/100*VLOOKUP(TRIM($B14),Base_bromato!$A:$AM,18,FALSE)) | AB13: =IF($B14="","",$D14/100*VLOOKUP(TRIM($B14),Base_bromato!$A:$AM,19,FALSE)) | AC13: =IF($B14="","",$D14/100*VLOOKUP(TRIM($B14),Base_bromato!$A:$AM,20,FALSE)) | AD13: =IF($B14="","",$D14/100*VLOOKUP(TRIM($B14),Base_bromato!$A:$AM,21,FALSE)) | AE13: =IF($B14="","",$D14/100*VLOOKUP(TRIM($B14),Base_bromato!$A:$AM,22,FALSE)) | AF13: =IF($B14="","",$D14/100*VLOOKUP(TRIM($B14),Base_bromato!$A:$AM,23,FALSE)) | AG13: =IF($B14="","",$D14/100*VLOOKUP(TRIM($B14),Base_bromato!$A:$AM,24,FALSE)) | AH13: =IF($B14="","",$D14/100*VLOOKUP(TRIM($B14),Base_bromato!$A:$AM,25,FALSE)) | AI13: =IF($B14="","",$D14/100*VLOOKUP(TRIM($B14),Base_bromato!$A:$AM,26,FALSE)) | AJ13: =IF($B14="","",$D14/100*VLOOKUP(TRIM($B14),Base_bromato!$A:$AM,27,FALSE)) | AK13: =IF($B14="","",$D14/100*VLOOKUP(TRIM($B14),Base_bromato!$A:$AM,28,FALSE)) | AL13: =IF($B14="","",$D14/100*VLOOKUP(TRIM($B14),Base_bromato!$A:$AM,29,FALSE)) | AM13: =IF($B14="","",$D14/100*VLOOKUP(TRIM($B14),Base_bromato!$A:$AM,30,FALSE)) | AN13: =IF($B14="","",$D14/100*VLOOKUP(TRIM($B14),Base_bromato!$A:$AM,31,FALSE)) | AO13: =IF($B14="","",$D14/100*VLOOKUP(TRIM($B14),Base_bromato!$A:$AM,32,FALSE)) | AP13: =IF($B14="","",$D14/100*VLOOKUP(TRIM($B14),Base_bromato!$A:$AM,33,FALSE)) | AQ13: =IF($B14="","",$D14/100*VLOOKUP(TRIM($B14),Base_bromato!$A:$AM,34,FALSE)) | AR13: =IF($B14="","",$D14/100*VLOOKUP(TRIM($B14),Base_bromato!$A:$AM,35,FALSE)) | AS13: =IF($B14="","",$D14/100*VLOOKUP(TRIM($B14),Base_bromato!$A:$AM,36,FALSE)) | AT13: =IF($B14="","",$D14/100*VLOOKUP(TRIM($B14),Base_bromato!$A:$AM,37,FALSE)) | AU13: =IF($B14="","",$D14/100*VLOOKUP(TRIM($B14),Base_bromato!$A:$AM,38,FALSE)) | AV13: =IF($B14="","",$D14/100*VLOOKUP(TRIM($B14),Base_bromato!$A:$AM,39,FALSE))
F14: =E14*D14 -> 0 | H14: Ca (%) | I14: =INDEX(Base_bromato!$C$68:$L$104,MATCH(Formular!H14,Base_bromato!$B$68:$B$104,0),MATCH(Formular!$E$3,Base_bromato!$C$67:$L$67,0)) -> 0,90-1,0 | J14: =IF(SUM(OFFSET($L$5,0,ROW()-5,15,1))=0,"",SUM(OFFSET($L$5,0,ROW()-5,15,1))) | L14: =IF($B15="","",$D15/100*VLOOKUP(TRIM($B15),Base_bromato!$A:$AM,3,FALSE)) | M14: =IF($B15="","",$D15/100*VLOOKUP(TRIM($B15),Base_bromato!$A:$AM,4,FALSE)) | N14: =IF($B15="","",$D15/100*VLOOKUP(TRIM($B15),Base_bromato!$A:$AM,5,FALSE)) | O14: =IF($B15="","",$D15/100*VLOOKUP(TRIM($B15),Base_bromato!$A:$AM,6,FALSE)) | P14: =IF($B15="","",$D15/100*VLOOKUP(TRIM($B15),Base_bromato!$A:$AM,7,FALSE)) | Q14: =IF($B15="","",$D15/100*VLOOKUP(TRIM($B15),Base_bromato!$A:$AM,8,FALSE)) | R14: =IF($B15="","",$D15/100*VLOOKUP(TRIM($B15),Base_bromato!$A:$AM,9,FALSE)) | S14: =IF($B15="","",$D15/100*VLOOKUP(TRIM($B15),Base_bromato!$A:$AM,10,FALSE)) | T14: =IF($B15="","",$D15/100*VLOOKUP(TRIM($B15),Base_bromato!$A:$AM,11,FALSE)) | U14: =IF($B15="","",$D15/100*VLOOKUP(TRIM($B15),Base_bromato!$A:$AM,12,FALSE)) | V14: =IF($B15="","",$D15/100*VLOOKUP(TRIM($B15),Base_bromato!$A:$AM,13,FALSE)) | W14: =IF($B15="","",$D15/100*VLOOKUP(TRIM($B15),Base_bromato!$A:$AM,14,FALSE)) | X14: =IF($B15="","",$D15/100*VLOOKUP(TRIM($B15),Base_bromato!$A:$AM,15,FALSE)) | Y14: =IF($B15="","",$D15/100*VLOOKUP(TRIM($B15),Base_bromato!$A:$AM,16,FALSE)) | Z14: =IF($B15="","",$D15/100*VLOOKUP(TRIM($B15),Base_bromato!$A:$AM,17,FALSE)) | AA14: =IF($B15="","",$D15/100*VLOOKUP(TRIM($B15),Base_bromato!$A:$AM,18,FALSE)) | AB14: =IF($B15="","",$D15/100*VLOOKUP(TRIM($B15),Base_bromato!$A:$AM,19,FALSE)) | AC14: =IF($B15="","",$D15/100*VLOOKUP(TRIM($B15),Base_bromato!$A:$AM,20,FALSE)) | AD14: =IF($B15="","",$D15/100*VLOOKUP(TRIM($B15),Base_bromato!$A:$AM,21,FALSE)) | AE14: =IF($B15="","",$D15/100*VLOOKUP(TRIM($B15),Base_bromato!$A:$AM,22,FALSE)) | AF14: =IF($B15="","",$D15/100*VLOOKUP(TRIM($B15),Base_bromato!$A:$AM,23,FALSE)) | AG14: =IF($B15="","",$D15/100*VLOOKUP(TRIM($B15),Base_bromato!$A:$AM,24,FALSE)) | AH14: =IF($B15="","",$D15/100*VLOOKUP(TRIM($B15),Base_bromato!$A:$AM,25,FALSE)) | AI14: =IF($B15="","",$D15/100*VLOOKUP(TRIM($B15),Base_bromato!$A:$AM,26,FALSE)) | AJ14: =IF($B15="","",$D15/100*VLOOKUP(TRIM($B15),Base_bromato!$A:$AM,27,FALSE)) | AK14: =IF($B15="","",$D15/100*VLOOKUP(TRIM($B15),Base_bromato!$A:$AM,28,FALSE)) | AL14: =IF($B15="","",$D15/100*VLOOKUP(TRIM($B15),Base_bromato!$A:$AM,29,FALSE)) | AM14: =IF($B15="","",$D15/100*VLOOKUP(TRIM($B15),Base_bromato!$A:$AM,30,FALSE)) | AN14: =IF($B15="","",$D15/100*VLOOKUP(TRIM($B15),Base_bromato!$A:$AM,31,FALSE)) | AO14: =IF($B15="","",$D15/100*VLOOKUP(TRIM($B15),Base_bromato!$A:$AM,32,FALSE)) | AP14: =IF($B15="","",$D15/100*VLOOKUP(TRIM($B15),Base_bromato!$A:$AM,33,FALSE)) | AQ14: =IF($B15="","",$D15/100*VLOOKUP(TRIM($B15),Base_bromato!$A:$AM,34,FALSE)) | AR14: =IF($B15="","",$D15/100*VLOOKUP(TRIM($B15),Base_bromato!$A:$AM,35,FALSE)) | AS14: =IF($B15="","",$D15/100*VLOOKUP(TRIM($B15),Base_bromato!$A:$AM,36,FALSE)) | AT14: =IF($B15="","",$D15/100*VLOOKUP(TRIM($B15),Base_bromato!$A:$AM,37,FALSE)) | AU14: =IF($B15="","",$D15/100*VLOOKUP(TRIM($B15),Base_bromato!$A:$AM,38,FALSE)) | AV14: =IF($B15="","",$D15/100*VLOOKUP(TRIM($B15),Base_bromato!$A:$AM,39,FALSE))
F15: =E15*D15 -> 0 | H15: P (%) | I15: =INDEX(Base_bromato!$C$68:$L$104,MATCH(Formular!H15,Base_bromato!$B$68:$B$104,0),MATCH(Formular!$E$3,Base_bromato!$C$67:$L$67,0)) -> 0,36-0,38 | J15: =IF(SUM(OFFSET($L$5,0,ROW()-5,15,1))=0,"",SUM(OFFSET($L$5,0,ROW()-5,15,1))) | L15: =IF($B16="","",$D16/100*VLOOKUP(TRIM($B16),Base_bromato!$A:$AM,3,FALSE)) | M15: =IF($B16="","",$D16/100*VLOOKUP(TRIM($B16),Base_bromato!$A:$AM,4,FALSE)) | N15: =IF($B16="","",$D16/100*VLOOKUP(TRIM($B16),Base_bromato!$A:$AM,5,FALSE)) | O15: =IF($B16="","",$D16/100*VLOOKUP(TRIM($B16),Base_bromato!$A:$AM,6,FALSE)) | P15: =IF($B16="","",$D16/100*VLOOKUP(TRIM($B16),Base_bromato!$A:$AM,7,FALSE)) | Q15: =IF($B16="","",$D16/100*VLOOKUP(TRIM($B16),Base_bromato!$A:$AM,8,FALSE)) | R15: =IF($B16="","",$D16/100*VLOOKUP(TRIM($B16),Base_bromato!$A:$AM,9,FALSE)) | S15: =IF($B16="","",$D16/100*VLOOKUP(TRIM($B16),Base_bromato!$A:$AM,10,FALSE)) | T15: =IF($B16="","",$D16/100*VLOOKUP(TRIM($B16),Base_bromato!$A:$AM,11,FALSE)) | U15: =IF($B16="","",$D16/100*VLOOKUP(TRIM($B16),Base_bromato!$A:$AM,12,FALSE)) | V15: =IF($B16="","",$D16/100*VLOOKUP(TRIM($B16),Base_bromato!$A:$AM,13,FALSE)) | W15: =IF($B16="","",$D16/100*VLOOKUP(TRIM($B16),Base_bromato!$A:$AM,14,FALSE)) | X15: =IF($B16="","",$D16/100*VLOOKUP(TRIM($B16),Base_bromato!$A:$AM,15,FALSE)) | Y15: =IF($B16="","",$D16/100*VLOOKUP(TRIM($B16),Base_bromato!$A:$AM,16,FALSE)) | Z15: =IF($B16="","",$D16/100*VLOOKUP(TRIM($B16),Base_bromato!$A:$AM,17,FALSE)) | AA15: =IF($B16="","",$D16/100*VLOOKUP(TRIM($B16),Base_bromato!$A:$AM,18,FALSE)) | AB15: =IF($B16="","",$D16/100*VLOOKUP(TRIM($B16),Base_bromato!$A:$AM,19,FALSE)) | AC15: =IF($B16="","",$D16/100*VLOOKUP(TRIM($B16),Base_bromato!$A:$AM,20,FALSE)) | AD15: =IF($B16="","",$D16/100*VLOOKUP(TRIM($B16),Base_bromato!$A:$AM,21,FALSE)) | AE15: =IF($B16="","",$D16/100*VLOOKUP(TRIM($B16),Base_bromato!$A:$AM,22,FALSE)) | AF15: =IF($B16="","",$D16/100*VLOOKUP(TRIM($B16),Base_bromato!$A:$AM,23,FALSE)) | AG15: =IF($B16="","",$D16/100*VLOOKUP(TRIM($B16),Base_bromato!$A:$AM,24,FALSE)) | AH15: =IF($B16="","",$D16/100*VLOOKUP(TRIM($B16),Base_bromato!$A:$AM,25,FALSE)) | AI15: =IF($B16="","",$D16/100*VLOOKUP(TRIM($B16),Base_bromato!$A:$AM,26,FALSE)) | AJ15: =IF($B16="","",$D16/100*VLOOKUP(TRIM($B16),Base_bromato!$A:$AM,27,FALSE)) | AK15: =IF($B16="","",$D16/100*VLOOKUP(TRIM($B16),Base_bromato!$A:$AM,28,FALSE)) | AL15: =IF($B16="","",$D16/100*VLOOKUP(TRIM($B16),Base_bromato!$A:$AM,29,FALSE)) | AM15: =IF($B16="","",$D16/100*VLOOKUP(TRIM($B16),Base_bromato!$A:$AM,30,FALSE)) | AN15: =IF($B16="","",$D16/100*VLOOKUP(TRIM($B16),Base_bromato!$A:$AM,31,FALSE)) | AO15: =IF($B16="","",$D16/100*VLOOKUP(TRIM($B16),Base_bromato!$A:$AM,32,FALSE)) | AP15: =IF($B16="","",$D16/100*VLOOKUP(TRIM($B16),Base_bromato!$A:$AM,33,FALSE)) | AQ15: =IF($B16="","",$D16/100*VLOOKUP(TRIM($B16),Base_bromato!$A:$AM,34,FALSE)) | AR15: =IF($B16="","",$D16/100*VLOOKUP(TRIM($B16),Base_bromato!$A:$AM,35,FALSE)) | AS15: =IF($B16="","",$D16/100*VLOOKUP(TRIM($B16),Base_bromato!$A:$AM,36,FALSE)) | AT15: =IF($B16="","",$D16/100*VLOOKUP(TRIM($B16),Base_bromato!$A:$AM,37,FALSE)) | AU15: =IF($B16="","",$D16/100*VLOOKUP(TRIM($B16),Base_bromato!$A:$AM,38,FALSE)) | AV15: =IF($B16="","",$D16/100*VLOOKUP(TRIM($B16),Base_bromato!$A:$AM,39,FALSE))
F16: =E16*D16 -> 0 | H16: Na (%) | I16: =INDEX(Base_bromato!$C$68:$L$104,MATCH(Formular!H16,Base_bromato!$B$68:$B$104,0),MATCH(Formular!$E$3,Base_bromato!$C$67:$L$67,0)) -> 0.15 | J16: =IF(SUM(OFFSET($L$5,0,ROW()-5,15,1))=0,"",SUM(OFFSET($L$5,0,ROW()-5,15,1))) | L16: =IF($B17="","",$D17/100*VLOOKUP(TRIM($B17),Base_bromato!$A:$AM,3,FALSE)) | M16: =IF($B17="","",$D17/100*VLOOKUP(TRIM($B17),Base_bromato!$A:$AM,4,FALSE)) | N16: =IF($B17="","",$D17/100*VLOOKUP(TRIM($B17),Base_bromato!$A:$AM,5,FALSE)) | O16: =IF($B17="","",$D17/100*VLOOKUP(TRIM($B17),Base_bromato!$A:$AM,6,FALSE)) | P16: =IF($B17="","",$D17/100*VLOOKUP(TRIM($B17),Base_bromato!$A:$AM,7,FALSE)) | Q16: =IF($B17="","",$D17/100*VLOOKUP(TRIM($B17),Base_bromato!$A:$AM,8,FALSE)) | R16: =IF($B17="","",$D17/100*VLOOKUP(TRIM($B17),Base_bromato!$A:$AM,9,FALSE)) | S16: =IF($B17="","",$D17/100*VLOOKUP(TRIM($B17),Base_bromato!$A:$AM,10,FALSE)) | T16: =IF($B17="","",$D17/100*VLOOKUP(TRIM($B17),Base_bromato!$A:$AM,11,FALSE)) | U16: =IF($B17="","",$D17/100*VLOOKUP(TRIM($B17),Base_bromato!$A:$AM,12,FALSE)) | V16: =IF($B17="","",$D17/100*VLOOKUP(TRIM($B17),Base_bromato!$A:$AM,13,FALSE)) | W16: =IF($B17="","",$D17/100*VLOOKUP(TRIM($B17),Base_bromato!$A:$AM,14,FALSE)) | X16: =IF($B17="","",$D17/100*VLOOKUP(TRIM($B17),Base_bromato!$A:$AM,15,FALSE)) | Y16: =IF($B17="","",$D17/100*VLOOKUP(TRIM($B17),Base_bromato!$A:$AM,16,FALSE)) | Z16: =IF($B17="","",$D17/100*VLOOKUP(TRIM($B17),Base_bromato!$A:$AM,17,FALSE)) | AA16: =IF($B17="","",$D17/100*VLOOKUP(TRIM($B17),Base_bromato!$A:$AM,18,FALSE)) | AB16: =IF($B17="","",$D17/100*VLOOKUP(TRIM($B17),Base_bromato!$A:$AM,19,FALSE)) | AC16: =IF($B17="","",$D17/100*VLOOKUP(TRIM($B17),Base_bromato!$A:$AM,20,FALSE)) | AD16: =IF($B17="","",$D17/100*VLOOKUP(TRIM($B17),Base_bromato!$A:$AM,21,FALSE)) | AE16: =IF($B17="","",$D17/100*VLOOKUP(TRIM($B17),Base_bromato!$A:$AM,22,FALSE)) | AF16: =IF($B17="","",$D17/100*VLOOKUP(TRIM($B17),Base_bromato!$A:$AM,23,FALSE)) | AG16: =IF($B17="","",$D17/100*VLOOKUP(TRIM($B17),Base_bromato!$A:$AM,24,FALSE)) | AH16: =IF($B17="","",$D17/100*VLOOKUP(TRIM($B17),Base_bromato!$A:$AM,25,FALSE)) | AI16: =IF($B17="","",$D17/100*VLOOKUP(TRIM($B17),Base_bromato!$A:$AM,26,FALSE)) | AJ16: =IF($B17="","",$D17/100*VLOOKUP(TRIM($B17),Base_bromato!$A:$AM,27,FALSE)) | AK16: =IF($B17="","",$D17/100*VLOOKUP(TRIM($B17),Base_bromato!$A:$AM,28,FALSE)) | AL16: =IF($B17="","",$D17/100*VLOOKUP(TRIM($B17),Base_bromato!$A:$AM,29,FALSE)) | AM16: =IF($B17="","",$D17/100*VLOOKUP(TRIM($B17),Base_bromato!$A:$AM,30,FALSE)) | AN16: =IF($B17="","",$D17/100*VLOOKUP(TRIM($B17),Base_bromato!$A:$AM,31,FALSE)) | AO16: =IF($B17="","",$D17/100*VLOOKUP(TRIM($B17),Base_bromato!$A:$AM,32,FALSE)) | AP16: =IF($B17="","",$D17/100*VLOOKUP(TRIM($B17),Base_bromato!$A:$AM,33,FALSE)) | AQ16: =IF($B17="","",$D17/100*VLOOKUP(TRIM($B17),Base_bromato!$A:$AM,34,FALSE)) | AR16: =IF($B17="","",$D17/100*VLOOKUP(TRIM($B17),Base_bromato!$A:$AM,35,FALSE)) | AS16: =IF($B17="","",$D17/100*VLOOKUP(TRIM($B17),Base_bromato!$A:$AM,36,FALSE)) | AT16: =IF($B17="","",$D17/100*VLOOKUP(TRIM($B17),Base_bromato!$A:$AM,37,FALSE)) | AU16: =IF($B17="","",$D17/100*VLOOKUP(TRIM($B17),Base_bromato!$A:$AM,38,FALSE)) | AV16: =IF($B17="","",$D17/100*VLOOKUP(TRIM($B17),Base_bromato!$A:$AM,39,FALSE))
F17: =E17*D17 -> 0 | H17: Val (%) | I17: =INDEX(Base_bromato!$C$68:$L$104,MATCH(Formular!H17,Base_bromato!$B$68:$B$104,0),MATCH(Formular!$E$3,Base_bromato!$C$67:$L$67,0)) -> 0.76 | J17: =IF(SUM(OFFSET($L$5,0,ROW()-5,15,1))=0,"",SUM(OFFSET($L$5,0,ROW()-5,15,1))) | L17: =IF($B18="","",$D18/100*VLOOKUP(TRIM($B18),Base_bromato!$A:$AM,3,FALSE)) | M17: =IF($B18="","",$D18/100*VLOOKUP(TRIM($B18),Base_bromato!$A:$AM,4,FALSE)) | N17: =IF($B18="","",$D18/100*VLOOKUP(TRIM($B18),Base_bromato!$A:$AM,5,FALSE)) | O17: =IF($B18="","",$D18/100*VLOOKUP(TRIM($B18),Base_bromato!$A:$AM,6,FALSE)) | P17: =IF($B18="","",$D18/100*VLOOKUP(TRIM($B18),Base_bromato!$A:$AM,7,FALSE)) | Q17: =IF($B18="","",$D18/100*VLOOKUP(TRIM($B18),Base_bromato!$A:$AM,8,FALSE)) | R17: =IF($B18="","",$D18/100*VLOOKUP(TRIM($B18),Base_bromato!$A:$AM,9,FALSE)) | S17: =IF($B18="","",$D18/100*VLOOKUP(TRIM($B18),Base_bromato!$A:$AM,10,FALSE)) | T17: =IF($B18="","",$D18/100*VLOOKUP(TRIM($B18),Base_bromato!$A:$AM,11,FALSE)) | U17: =IF($B18="","",$D18/100*VLOOKUP(TRIM($B18),Base_bromato!$A:$AM,12,FALSE)) | V17: =IF($B18="","",$D18/100*VLOOKUP(TRIM($B18),Base_bromato!$A:$AM,13,FALSE)) | W17: =IF($B18="","",$D18/100*VLOOKUP(TRIM($B18),Base_bromato!$A:$AM,14,FALSE)) | X17: =IF($B18="","",$D18/100*VLOOKUP(TRIM($B18),Base_bromato!$A:$AM,15,FALSE)) | Y17: =IF($B18="","",$D18/100*VLOOKUP(TRIM($B18),Base_bromato!$A:$AM,16,FALSE)) | Z17: =IF($B18="","",$D18/100*VLOOKUP(TRIM($B18),Base_bromato!$A:$AM,17,FALSE)) | AA17: =IF($B18="","",$D18/100*VLOOKUP(TRIM($B18),Base_bromato!$A:$AM,18,FALSE)) | AB17: =IF($B18="","",$D18/100*VLOOKUP(TRIM($B18),Base_bromato!$A:$AM,19,FALSE)) | AC17: =IF($B18="","",$D18/100*VLOOKUP(TRIM($B18),Base_bromato!$A:$AM,20,FALSE)) | AD17: =IF($B18="","",$D18/100*VLOOKUP(TRIM($B18),Base_bromato!$A:$AM,21,FALSE)) | AE17: =IF($B18="","",$D18/100*VLOOKUP(TRIM($B18),Base_bromato!$A:$AM,22,FALSE)) | AF17: =IF($B18="","",$D18/100*VLOOKUP(TRIM($B18),Base_bromato!$A:$AM,23,FALSE)) | AG17: =IF($B18="","",$D18/100*VLOOKUP(TRIM($B18),Base_bromato!$A:$AM,24,FALSE)) | AH17: =IF($B18="","",$D18/100*VLOOKUP(TRIM($B18),Base_bromato!$A:$AM,25,FALSE)) | AI17: =IF($B18="","",$D18/100*VLOOKUP(TRIM($B18),Base_bromato!$A:$AM,26,FALSE)) | AJ17: =IF($B18="","",$D18/100*VLOOKUP(TRIM($B18),Base_bromato!$A:$AM,27,FALSE)) | AK17: =IF($B18="","",$D18/100*VLOOKUP(TRIM($B18),Base_bromato!$A:$AM,28,FALSE)) | AL17: =IF($B18="","",$D18/100*VLOOKUP(TRIM($B18),Base_bromato!$A:$AM,29,FALSE)) | AM17: =IF($B18="","",$D18/100*VLOOKUP(TRIM($B18),Base_bromato!$A:$AM,30,FALSE)) | AN17: =IF($B18="","",$D18/100*VLOOKUP(TRIM($B18),Base_bromato!$A:$AM,31,FALSE)) | AO17: =IF($B18="","",$D18/100*VLOOKUP(TRIM($B18),Base_bromato!$A:$AM,32,FALSE)) | AP17: =IF($B18="","",$D18/100*VLOOKUP(TRIM($B18),Base_bromato!$A:$AM,33,FALSE)) | AQ17: =IF($B18="","",$D18/100*VLOOKUP(TRIM($B18),Base_bromato!$A:$AM,34,FALSE)) | AR17: =IF($B18="","",$D18/100*VLOOKUP(TRIM($B18),Base_bromato!$A:$AM,35,FALSE)) | AS17: =IF($B18="","",$D18/100*VLOOKUP(TRIM($B18),Base_bromato!$A:$AM,36,FALSE)) | AT17: =IF($B18="","",$D18/100*VLOOKUP(TRIM($B18),Base_bromato!$A:$AM,37,FALSE)) | AU17: =IF($B18="","",$D18/100*VLOOKUP(TRIM($B18),Base_bromato!$A:$AM,38,FALSE)) | AV17: =IF($B18="","",$D18/100*VLOOKUP(TRIM($B18),Base_bromato!$A:$AM,39,FALSE))
F18: =E18*D18 -> 0 | H18: Cl (g/Kg) | I18: =INDEX(Base_bromato!$C$68:$L$104,MATCH(Formular!H18,Base_bromato!$B$68:$B$104,0),MATCH(Formular!$E$3,Base_bromato!$C$67:$L$67,0)) -> 0.14 | J18: =IF(SUM(OFFSET($L$5,0,ROW()-5,15,1))=0,"",SUM(OFFSET($L$5,0,ROW()-5,15,1))) | L18: =IF($B19="","",$D19/100*VLOOKUP(TRIM($B19),Base_bromato!$A:$AM,3,FALSE)) | M18: =IF($B19="","",$D19/100*VLOOKUP(TRIM($B19),Base_bromato!$A:$AM,4,FALSE)) | N18: =IF($B19="","",$D19/100*VLOOKUP(TRIM($B19),Base_bromato!$A:$AM,5,FALSE)) | O18: =IF($B19="","",$D19/100*VLOOKUP(TRIM($B19),Base_bromato!$A:$AM,6,FALSE)) | P18: =IF($B19="","",$D19/100*VLOOKUP(TRIM($B19),Base_bromato!$A:$AM,7,FALSE)) | Q18: =IF($B19="","",$D19/100*VLOOKUP(TRIM($B19),Base_bromato!$A:$AM,8,FALSE)) | R18: =IF($B19="","",$D19/100*VLOOKUP(TRIM($B19),Base_bromato!$A:$AM,9,FALSE)) | S18: =IF($B19="","",$D19/100*VLOOKUP(TRIM($B19),Base_bromato!$A:$AM,10,FALSE)) | T18: =IF($B19="","",$D19/100*VLOOKUP(TRIM($B19),Base_bromato!$A:$AM,11,FALSE)) | U18: =IF($B19="","",$D19/100*VLOOKUP(TRIM($B19),Base_bromato!$A:$AM,12,FALSE)) | V18: =IF($B19="","",$D19/100*VLOOKUP(TRIM($B19),Base_bromato!$A:$AM,13,FALSE)) | W18: =IF($B19="","",$D19/100*VLOOKUP(TRIM($B19),Base_bromato!$A:$AM,14,FALSE)) | X18: =IF($B19="","",$D19/100*VLOOKUP(TRIM($B19),Base_bromato!$A:$AM,15,FALSE)) | Y18: =IF($B19="","",$D19/100*VLOOKUP(TRIM($B19),Base_bromato!$A:$AM,16,FALSE)) | Z18: =IF($B19="","",$D19/100*VLOOKUP(TRIM($B19),Base_bromato!$A:$AM,17,FALSE)) | AA18: =IF($B19="","",$D19/100*VLOOKUP(TRIM($B19),Base_bromato!$A:$AM,18,FALSE)) | AB18: =IF($B19="","",$D19/100*VLOOKUP(TRIM($B19),Base_bromato!$A:$AM,19,FALSE)) | AC18: =IF($B19="","",$D19/100*VLOOKUP(TRIM($B19),Base_bromato!$A:$AM,20,FALSE)) | AD18: =IF($B19="","",$D19/100*VLOOKUP(TRIM($B19),Base_bromato!$A:$AM,21,FALSE)) | AE18: =IF($B19="","",$D19/100*VLOOKUP(TRIM($B19),Base_bromato!$A:$AM,22,FALSE)) | AF18: =IF($B19="","",$D19/100*VLOOKUP(TRIM($B19),Base_bromato!$A:$AM,23,FALSE)) | AG18: =IF($B19="","",$D19/100*VLOOKUP(TRIM($B19),Base_bromato!$A:$AM,24,FALSE)) | AH18: =IF($B19="","",$D19/100*VLOOKUP(TRIM($B19),Base_bromato!$A:$AM,25,FALSE)) | AI18: =IF($B19="","",$D19/100*VLOOKUP(TRIM($B19),Base_bromato!$A:$AM,26,FALSE)) | AJ18: =IF($B19="","",$D19/100*VLOOKUP(TRIM($B19),Base_bromato!$A:$AM,27,FALSE)) | AK18: =IF($B19="","",$D19/100*VLOOKUP(TRIM($B19),Base_bromato!$A:$AM,28,FALSE)) | AL18: =IF($B19="","",$D19/100*VLOOKUP(TRIM($B19),Base_bromato!$A:$AM,29,FALSE)) | AM18: =IF($B19="","",$D19/100*VLOOKUP(TRIM($B19),Base_bromato!$A:$AM,30,FALSE)) | AN18: =IF($B19="","",$D19/100*VLOOKUP(TRIM($B19),Base_bromato!$A:$AM,31,FALSE)) | AO18: =IF($B19="","",$D19/100*VLOOKUP(TRIM($B19),Base_bromato!$A:$AM,32,FALSE)) | AP18: =IF($B19="","",$D19/100*VLOOKUP(TRIM($B19),Base_bromato!$A:$AM,33,FALSE)) | AQ18: =IF($B19="","",$D19/100*VLOOKUP(TRIM($B19),Base_bromato!$A:$AM,34,FALSE)) | AR18: =IF($B19="","",$D19/100*VLOOKUP(TRIM($B19),Base_bromato!$A:$AM,35,FALSE)) | AS18: =IF($B19="","",$D19/100*VLOOKUP(TRIM($B19),Base_bromato!$A:$AM,36,FALSE)) | AT18: =IF($B19="","",$D19/100*VLOOKUP(TRIM($B19),Base_bromato!$A:$AM,37,FALSE)) | AU18: =IF($B19="","",$D19/100*VLOOKUP(TRIM($B19),Base_bromato!$A:$AM,38,FALSE)) | AV18: =IF($B19="","",$D19/100*VLOOKUP(TRIM($B19),Base_bromato!$A:$AM,39,FALSE))
... F28: =E28*D28 -> 0 | H28: Vit D3 (IU/kg) | I28: =INDEX(Base_bromato!$C$68:$L$104,MATCH(Formular!H28,Base_bromato!$B$68:$B$104,0),MATCH(Formular!$E$3,Base_bromato!$C$67:$L$67,0)) -> 2000 | J28: =IF(SUM(OFFSET($L$5,0,ROW()-5,15,1))=0,"",SUM(OFFSET($L$5,0,ROW()-5,15,1))) | L28: =IF($B29="","",$D29/100*VLOOKUP(TRIM($B29),Base_bromato!$A:$AM,3,FALSE)) | M28: =IF($B29="","",$D29/100*VLOOKUP(TRIM($B29),Base_bromato!$A:$AM,4,FALSE)) | N28: =IF($B29="","",$D29/100*VLOOKUP(TRIM($B29),Base_bromato!$A:$AM,5,FALSE)) | O28: =IF($B29="","",$D29/100*VLOOKUP(TRIM($B29),Base_bromato!$A:$AM,6,FALSE)) | P28: =IF($B29="","",$D29/100*VLOOKUP(TRIM($B29),Base_bromato!$A:$AM,7,FALSE)) | Q28: =IF($B29="","",$D29/100*VLOOKUP(TRIM($B29),Base_bromato!$A:$AM,8,FALSE)) | R28: =IF($B29="","",$D29/100*VLOOKUP(TRIM($B29),Base_bromato!$A:$AM,9,FALSE)) | S28: =IF($B29="","",$D29/100*VLOOKUP(TRIM($B29),Base_bromato!$A:$AM,10,FALSE)) | T28: =IF($B29="","",$D29/100*VLOOKUP(TRIM($B29),Base_bromato!$A:$AM,11,FALSE)) | U28: =IF($B29="","",$D29/100*VLOOKUP(TRIM($B29),Base_bromato!$A:$AM,12,FALSE)) | V28: =IF($B29="","",$D29/100*VLOOKUP(TRIM($B29),Base_bromato!$A:$AM,13,FALSE)) | W28: =IF($B29="","",$D29/100*VLOOKUP(TRIM($B29),Base_bromato!$A:$AM,14,FALSE)) | X28: =IF($B29="","",$D29/100*VLOOKUP(TRIM($B29),Base_bromato!$A:$AM,15,FALSE)) | Y28: =IF($B29="","",$D29/100*VLOOKUP(TRIM($B29),Base_bromato!$A:$AM,16,FALSE)) | Z28: =IF($B29="","",$D29/100*VLOOKUP(TRIM($B29),Base_bromato!$A:$AM,17,FALSE)) | AA28: =IF($B29="","",$D29/100*VLOOKUP(TRIM($B29),Base_bromato!$A:$AM,18,FALSE)) | AB28: =IF($B29="","",$D29/100*VLOOKUP(TRIM($B29),Base_bromato!$A:$AM,19,FALSE)) | AC28: =IF($B29="","",$D29/100*VLOOKUP(TRIM($B29),Base_bromato!$A:$AM,20,FALSE)) | AD28: =IF($B29="","",$D29/100*VLOOKUP(TRIM($B29),Base_bromato!$A:$AM,21,FALSE)) | AE28: =IF($B29="","",$D29/100*VLOOKUP(TRIM($B29),Base_bromato!$A:$AM,22,FALSE)) | AF28: =IF($B29="","",$D29/100*VLOOKUP(TRIM($B29),Base_bromato!$A:$AM,23,FALSE)) | AG28: =IF($B29="","",$D29/100*VLOOKUP(TRIM($B29),Base_bromato!$A:$AM,24,FALSE)) | AH28: =IF($B29="","",$D29/100*VLOOKUP(TRIM($B29),Base_bromato!$A:$AM,25,FALSE)) | AI28: =IF($B29="","",$D29/100*VLOOKUP(TRIM($B29),Base_bromato!$A:$AM,26,FALSE)) | AJ28: =IF($B29="","",$D29/100*VLOOKUP(TRIM($B29),Base_bromato!$A:$AM,27,FALSE)) | AK28: =IF($B29="","",$D29/100*VLOOKUP(TRIM($B29),Base_bromato!$A:$AM,28,FALSE)) | AL28: =IF($B29="","",$D29/100*VLOOKUP(TRIM($B29),Base_bromato!$A:$AM,29,FALSE)) | AM28: =IF($B29="","",$D29/100*VLOOKUP(TRIM($B29),Base_bromato!$A:$AM,30,FALSE)) | AN28: =IF($B29="","",$D29/100*VLOOKUP(TRIM($B29),Base_bromato!$A:$AM,31,FALSE)) | AO28: =IF($B29="","",$D29/100*VLOOKUP(TRIM($B29),Base_bromato!$A:$AM,32,FALSE)) | AP28: =IF($B29="","",$D29/100*VLOOKUP(TRIM($B29),Base_bromato!$A:$AM,33,FALSE)) | AQ28: =IF($B29="","",$D29/100*VLOOKUP(TRIM($B29),Base_bromato!$A:$AM,34,FALSE)) | AR28: =IF($B29="","",$D29/100*VLOOKUP(TRIM($B29),Base_bromato!$A:$AM,35,FALSE)) | AS28: =IF($B29="","",$D29/100*VLOOKUP(TRIM($B29),Base_bromato!$A:$AM,36,FALSE)) | AT28: =IF($B29="","",$D29/100*VLOOKUP(TRIM($B29),Base_bromato!$A:$AM,37,FALSE)) | AU28: =IF($B29="","",$D29/100*VLOOKUP(TRIM($B29),Base_bromato!$A:$AM,38,FALSE)) | AV28: =IF($B29="","",$D29/100*VLOOKUP(TRIM($B29),Base_bromato!$A:$AM,39,FALSE))
F29: =E29*D29 -> 0 | H29: Vit E (IU/kg) | I29: =INDEX(Base_bromato!$C$68:$L$104,MATCH(Formular!H29,Base_bromato!$B$68:$B$104,0),MATCH(Formular!$E$3,Base_bromato!$C$67:$L$67,0)) -> 15 | J29: =IF(SUM(OFFSET($L$5,0,ROW()-5,15,1))=0,"",SUM(OFFSET($L$5,0,ROW()-5,15,1))) | L29: =+SUM(L5:L28) -> 0 | M29: =+SUM(M5:M28) -> 0 | N29: =+SUM(N5:N28) -> 0 | O29: =+SUM(O5:O28) -> 0 | P29: =+SUM(P5:P28) -> 0 | Q29: =+SUM(Q5:Q28) -> 0 | R29: =+SUM(R5:R28) -> 0 | S29: =+SUM(S5:S28) -> 0 | ... AV29: =+SUM(AV5:AV28) -> 0
B30: TOTAL | D30: =SUM(D6:D29) -> 0 | E30: =+F30/D30 -> #DIV/0! | F30: =SUM(F6:F29) -> 0 | H30: Vit K (IU/kg) | I30: =INDEX(Base_bromato!$C$68:$L$104,MATCH(Formular!H30,Base_bromato!$B$68:$B$104,0),MATCH(Formular!$E$3,Base_bromato!$C$67:$L$67,0)) -> 2 | J30: =IF(SUM(OFFSET($L$5,0,ROW()-5,15,1))=0,"",SUM(OFFSET($L$5,0,ROW()-5,15,1)))
H31: Chol (mg/Kg) | I31: =INDEX(Base_bromato!$C$68:$L$104,MATCH(Formular!H31,Base_bromato!$B$68:$B$104,0),MATCH(Formular!$E$3,Base_bromato!$C$67:$L$67,0)) -> 900 | J31: =IF(SUM(OFFSET($L$5,0,ROW()-5,15,1))=0,"",SUM(OFFSET($L$5,0,ROW()-5,15,1)))
H32: A. folique (mg/Kg) | I32: =INDEX(Base_bromato!$C$68:$L$104,MATCH(Formular!H32,Base_bromato!$B$68:$B$104,0),MATCH(Formular!$E$3,Base_bromato!$C$67:$L$67,0)) -> 0.6 | J32: =IF(SUM(OFFSET($L$5,0,ROW()-5,15,1))=0,"",SUM(OFFSET($L$5,0,ROW()-5,15,1)))
H33: A.nico(mg/Kg) | I33: =INDEX(Base_bromato!$C$68:$L$104,MATCH(Formular!H33,Base_bromato!$B$68:$B$104,0),MATCH(Formular!$E$3,Base_bromato!$C$67:$L$67,0)) -> 25 | J33: =IF(SUM(OFFSET($L$5,0,ROW()-5,15,1))=0,"",SUM(OFFSET($L$5,0,ROW()-5,15,1)))
H34: A.Panto (mg/Kg) | I34: =INDEX(Base_bromato!$C$68:$L$104,MATCH(Formular!H34,Base_bromato!$B$68:$B$104,0),MATCH(Formular!$E$3,Base_bromato!$C$67:$L$67,0)) -> 8 | J34: =IF(SUM(OFFSET($L$5,0,ROW()-5,15,1))=0,"",SUM(OFFSET($L$5,0,ROW()-5,15,1)))
H35: Mn (mg/Kg) | I35: =INDEX(Base_bromato!$C$68:$L$104,MATCH(Formular!H35,Base_bromato!$B$68:$B$104,0),MATCH(Formular!$E$3,Base_bromato!$C$67:$L$67,0)) -> 60 | J35: =IF(SUM(OFFSET($L$5,0,ROW()-5,15,1))=0,"",SUM(OFFSET($L$5,0,ROW()-5,15,1)))
H36: Zn (mg/Kg) | I36: =INDEX(Base_bromato!$C$68:$L$104,MATCH(Formular!H36,Base_bromato!$B$68:$B$104,0),MATCH(Formular!$E$3,Base_bromato!$C$67:$L$67,0)) -> 50 | J36: =IF(SUM(OFFSET($L$5,0,ROW()-5,15,1))=0,"",SUM(OFFSET($L$5,0,ROW()-5,15,1)))
H37: Cu (mg/Kg) | I37: =INDEX(Base_bromato!$C$68:$L$104,MATCH(Formular!H37,Base_bromato!$B$68:$B$104,0),MATCH(Formular!$E$3,Base_bromato!$C$67:$L$67,0)) -> 6 | J37: =IF(SUM(OFFSET($L$5,0,ROW()-5,15,1))=0,"",SUM(OFFSET($L$5,0,ROW()-5,15,1)))
H38: Fer (mg/Kg) | I38: =INDEX(Base_bromato!$C$68:$L$104,MATCH(Formular!H38,Base_bromato!$B$68:$B$104,0),MATCH(Formular!$E$3,Base_bromato!$C$67:$L$67,0)) -> 50 | J38: =IF(SUM(OFFSET($L$5,0,ROW()-5,15,1))=0,"",SUM(OFFSET($L$5,0,ROW()-5,15,1)))
H39: Iode (mg/Kg) | I39: =INDEX(Base_bromato!$C$68:$L$104,MATCH(Formular!H39,Base_bromato!$B$68:$B$104,0),MATCH(Formular!$E$3,Base_bromato!$C$67:$L$67,0)) -> 0.6 | J39: =IF(SUM(OFFSET($L$5,0,ROW()-5,15,1))=0,"",SUM(OFFSET($L$5,0,ROW()-5,15,1)))
H40: Sélénium (mg/Kg) | I40: =INDEX(Base_bromato!$C$68:$L$104,MATCH(Formular!H40,Base_bromato!$B$68:$B$104,0),MATCH(Formular!$E$3,Base_bromato!$C$67:$L$67,0)) -> 0.15 | J40: =IF(SUM(OFFSET($L$5,0,ROW()-5,15,1))=0,"",SUM(OFFSET($L$5,0,ROW()-5,15,1)))
H41: Cobalt (mg/Kg) | I41: =INDEX(Base_bromato!$C$68:$L$104,MATCH(Formular!H41,Base_bromato!$B$68:$B$104,0),MATCH(Formular!$E$3,Base_bromato!$C$67:$L$67,0)) -> 0.2 | J41: =IF(SUM(OFFSET($L$5,0,ROW()-5,15,1))=0,"",SUM(OFFSET($L$5,0,ROW()-5,15,1)))

Sheet Base_bromato
A1: Ingrédients alimentaires | C1: EM(kcal/Kg) | D1: Fibres crues (%) | E1: Matières grasses (%) | F1: PB(%) | G1: Lys(%) | H1: Mét (%) | I1: Mét+Cys (%) | J1: Thr (%) | K1: Trp (%) | L1: Ca (%) | M1: P (%) | N1: Na (%) | O1: Val (%) | P1: Cl (g/Kg) | Q1: Arg (g/Kg) | R1: Isl (%) | S1: K (g/Kg) | T1: A. Linol (%) | U1: Vit A (IU/kg) | V1: Vit B1 (mg/Kg) | W1: Vit B2 (mg/Kg) | X1: Vit B6 (mg/Kg) | Y1: Vit B12 (mg/Kg) | Z1: Vit D3 (IU/kg) | AA1: Vit E (IU/kg) | AB1: Vit K (IU/kg) | AC1: Chol (mg/Kg) | AD1: A. folique (mg/Kg) | AE1: A.nico(mg/Kg) | AF1: A.Panto (mg/Kg) | AG1: Mn (mg/Kg) | AH1: Zn (mg/Kg) | AI1: Cu (mg/Kg) | AJ1: Fer (mg/Kg) | AK1: Iode (mg/Kg) | AL1: Sélénium (mg/Kg) | AM1: Cobalt (mg/Kg)
A2: Grain de Maïs | C2: 3300 | D2: 2.2 | E2: 4.2 | F2: 7.5 | G2: 0.23 | H2: 0.16 | I2: 0.33 | J2: 0.27 | K2: 0.07 | L2: 0.02 | M2: 0.1 | N2: 0.01 | O2: 0.4 | P2: 0.04 | Q2: 0.42 | R2: 0.3 | S2: 0.35 | T2: 1.9 | U2: 0 | V2: 1.8 | W2: 0.7 | X2: 2.3 | Y2: 0 | Z2: 0 | AA2: 8.55 | AB2: 0.15 | AC2: 620 | AD2: 0.3 | AE2: 20 | AF2: 5.5 | AG2: 7 | AH2: 20 | AI2: 3.5 | AJ2: 35 | AK2: 0.05 | AL2: 0.06 | AM2: 0.05
A3: Son de maïs | C3: 2228 | D3: 9 | E3: 4.5 | F3: 10.1 | G3: 0.25 | H3: 0.15 | I3: 0.36 | J3: 0.35 | K3: 0.08 | L3: 0.03 | M3: 0.08 | N3: 0.02 | O3: 0.45 | P3: 0.05 | Q3: 0.6 | R3: 0.35 | S3: 0.6 | T3: 0.85 | U3: 0 | V3: 4.5 | W3: 1.1 | X3: 5.5 | Y3: 0 | Z3: 0 | AA3: 15 | AB3: 0.2 | AC3: 850 | AD3: 0.3 | AE3: 35 | AF3: 8 | AG3: 15 | AH3: 45 | AI3: 6 | AJ3: 80 | AK3: 0.08 | AL3: 0.1 | AM3: 0.08
A4: Grain de mil | C4: 2800 | D4: 3 | E4: 4 | F4: 11 | G4: 0.25 | H4: 0.2 | I4: 0.38 | J4: 0.38 | K4: 0.18 | L4: 0.05 | M4: 0.28 | N4: 0.01 | O4: 0.5 | P4: 0.04 | Q4: 0.5 | R4: 0.45 | S4: 0.42 | T4: 1.1 | U4: 0 | V4: 3.8 | W4: 1.8 | X4: 3.9 | Y4: 0 | Z4: 0 | AA4: 4.5 | AB4: 0.1 | AC4: 780 | AD4: 0.25 | AE4: 25 | AF4: 7.5 | AG4: 12 | AH4: 28 | AI4: 5 | AJ4: 70 | AK4: 0.06 | AL4: 0.08 | AM4: 0.06
A5: Son de riz | C5: 2850 | D5: 12.5 | E5: 13.5 | F5: 13.5 | G5: 0.61 | H5: 0.26 | I5: 0.42 | J5: 0.5 | K5: 0.17 | L5: 0.07 | M5: 1.4 | N5: 0.05 | O5: 0.71 | P5: 0.08 | Q5: 1.05 | R5: 0.46 | S5: 1.15 | AG5: 110 | AH5: 60 | AI5: 12 | AJ5: 180 | AK5: 0.3 | AL5: 0.35 | AM5: 0.15
A6: Grain de Sorgho | C6: 3175 | D6: 2.5 | E6: 3 | F6: 9 | G6: 0.24 | H6: 0.16 | I6: 0.34 | J6: 0.3 | K6: 0.1 | L6: 0.04 | M6: 0.1 | N6: 0.01 | O6: 0.45 | P6: 0.05 | Q6: 0.38 | R6: 0.35 | S6: 0.38 | T6: 1 | U6: 0 | V6: 3.9 | W6: 1.3 | X6: 3.2 | Y6: 0 | Z6: 0 | AA6: 7.5 | AB6: 0.12 | AC6: 700 | AD6: 0.28 | AE6: 38 | AF6: 8.5 | AG6: 15 | AH6: 25 | AI6: 8 | AJ6: 85 | AK6: 0.07 | AL6: 0.15 | AM6: 0.07
A7: Son cubé | C7: 1800 | D7: 8.5 | E7: 4.2 | F7: 15.5 | G7: 0.55 | H7: 0.22 | I7: 0.48 | J7: 0.5 | K7: 0.22 | L7: 0.12 | M7: 0.35 | N7: 0.04 | O7: 0.7 | P7: 0.06 | Q7: 0.95 | R7: 0.6 | S7: 1.15 | T7: 0.65 | U7: 0 | V7: 8 | W7: 3 | X7: 6.8 | Y7: 0 | Z7: 0 | AA7: 20 | AB7: 0.3 | AC7: 1100 | AD7: 0.75 | AE7: 180 | AF7: 22 | AG7: 110 | AH7: 90 | AI7: 12 | AJ7: 180 | AK7: 0.15 | AL7: 0.35 | AM7: 0.12
A8: Son de blé | C8: 1440 | D8: 9.6 | E8: 4.5 | F8: 16 | G8: 0.58 | H8: 0.23 | I8: 0.45 | J8: 0.48 | K8: 0.2 | L8: 0.14 | M8: 0.4 | N8: 0.05 | O8: 0.65 | P8: 0.07 | Q8: 1 | R8: 0.65 | S8: 1.18 | T8: 0.7 | U8: 0 | V8: 8.5 | W8: 3.5 | X8: 7.2 | Y8: 0 | Z8: 0 | AA8: 22 | AB8: 0.35 | AC8: 1250 | AD8: 0.9 | AE8: 195 | AF8: 25 | AG8: 115 | AH8: 95 | AI8: 13 | AJ8: 190 | AK8: 0.16 | AL8: 0.38 | AM8: 0.13
A9: Concentré chair 5% | C9: 2800 | D9: 2.4 | E9: 5.3 | F9: 31.2 | G9: 4.4 | H9: 3.5 | I9: 4.2 | J9: 0 | K9: 0 | L9: 10.2 | M9: 4.6 | N9: 2.9 | O9: 0 | P9: 0 | Q9: 0 | R9: 1.4 | S9: 0.7 | T9: 0.4 | U9: 200000 | V9: 20 | W9: 80 | X9: 30 | Y9: 0.25 | Z9: 40000 | AA9: 400 | AB9: 20 | AC9: 6000 | AD9: 12 | AE9: 450 | AF9: 180 | AG9: 1600 | AH9: 1500 | AI9: 300 | AJ9: 1000 | AK9: 25 | AL9: 5 | AM9: 8
A10: Concentré chair 10% | C10: 2590 | D10: 2.4 | E10: 4.3 | F10: 48 | G10: 7.2 | H10: 3 | I10: 7 | J10: 0 | K10: 0 | L10: 1.9 | M10: 2.8 | N10: 1.9 | O10: 0 | P10: 0 | Q10: 0 | R10: 1.2 | S10: 0.65 | T10: 0.35 | U10: 150000 | V10: 15 | W10: 60 | X10: 25 | Y10: 0.2 | Z10: 30000 | AA10: 300 | AB10: 15 | AC10: 5000 | AD10: 10 | AE10: 350 | AF10: 140 | AG10: 1200 | AH10: 1100 | AI10: 220 | AJ10: 800 | AK10: 18 | AL10: 3.5 | AM10: 6
A11: Concentré Ponte 5% jaunissant | C11: 2200 | D11: 9.5 | E11: 2.7 | F11: 30 | G11: 2.8 | H11: 2.4 | I11: 2.5 | J11: 0 | K11: 0 | L11: 2.8 | M11: 3.3 | N11: 2.9 | O11: 0 | P11: 0 | Q11: 0 | R11: 1.65 | S11: 0.75 | T11: 0.45 | U11: 250000 | V11: 25 | W11: 90 | X11: 35 | Y11: 0.3 | Z11: 50000 | AA11: 500 | AB11: 25 | AC11: 6500 | AD11: 15 | AE11: 500 | AF11: 200 | AG11: 1800 | AH11: 1700 | AI11: 350 | AJ11: 1200 | AK11: 30 | AL11: 6 | AM11: 10
A12: Concentré rearer 5% | C12: 3740 | D12: 3.5 | E12: 7 | F12: 37.2 | G12: 2.2 | H12: 2.3 | I12: 2.5 | J12: 0 | K12: 0 | L12: 1.5 | M12: 4 | N12: 2.8 | O12: 0 | P12: 0 | Q12: 0 | R12: 1.5 | S12: 0.7 | T12: 0.4 | U12: 220000 | V12: 22 | W12: 85 | X12: 32 | Y12: 0.28 | Z12: 45000 | AA12: 450 | AB12: 22 | AC12: 6200 | AD12: 13 | AE12: 480 | AF12: 190 | AG12: 1700 | AH12: 1600 | AI12: 320 | AJ12: 1100 | AK12: 28 | AL12: 5.5 | AM12: 9
A13: Huile de palme (Rouge) | C13: 8600 | D13: 0 | E13: 100 | F13: 0 | G13: 0 | H13: 0 | I13: 0 | J13: 0 | K13: 0 | L13: 0 | M13: 0 | N13: 0 | O13: 0 | P13: 0 | Q13: 0 | R13: 0 | S13: 0 | T13: 9 | U13: 0 | V13: 0 | W13: 0 | X13: 0 | Y13: 0 | Z13: 0 | AA13: 80 | AB13: 0 | AC13: 0 | AD13: 0 | AE13: 0 | AF13: 0 | AG13: 0 | AH13: 0 | AI13: 0 | AJ13: 0 | AK13: 0 | AL13: 0 | AM13: 0
A14: Tourteau de coton | C14: 2368 | D14: 14.6 | E14: 4.6 | F14: 42.5 | G14: 1.72 | H14: 0.59 | I14: 1.24 | J14: 1.35 | K14: 0.5 | L14: 0.2 | M14: 0.3 | N14: 0.05 | O14: 1.8 | P14: 0.04 | Q14: 4.2 | R14: 1.4 | S14: 1.2 | T14: 0.5 | U14: 0 | V14: 5.2 | W14: 4.1 | X14: 6.5 | Y14: 0 | Z14: 0 | AA14: 8.5 | AB14: 0.18 | AC14: 2100 | AD14: 1.15 | AE14: 35 | AF14: 10 | AG14: 20 | AH14: 65 | AI14: 15 | AJ14: 200 | AK14: 0.18 | AL14: 0.3 | AM14: 0.2
A15: Soja grain torifié | C15: 3900 | D15: 6 | E15: 17.9 | F15: 37 | G15: 2.35 | H15: 0.52 | I15: 1.15 | J15: 1.45 | K15: 0.48 | L15: 0.25 | M15: 0.2 | N15: 0.01 | O15: 1.8 | P15: 0.03 | Q15: 2.65 | R15: 1.85 | S15: 1.8 | T15: 9.5 | U15: 0 | V15: 6.5 | W15: 2.8 | X15: 5 | Y15: 0 | Z15: 0 | AA15: 3 | AB15: 0.4 | AC15: 2700 | AD15: 0.85 | AE15: 24 | AF15: 15 | AG15: 30 | AH15: 45 | AI15: 12 | AJ15: 120 | AK15: 0.12 | AL15: 0.08 | AM15: 0.15
A16: Tourteau de Soja 42 | C16: 2280 | D16: 5.5 | E16: 3.5 | F16: 42.5 | G16: 2.54 | H16: 0.59 | I16: 1.24 | J16: 1.8 | K16: 0.6 | L16: 0.34 | M16: 0.6 | N16: 0.04 | P16: 0.02 | Q16: 3.3 | R16: 2.2 | S16: 1.71 | T16: 1.8 | U16: 0 | V16: 6 | W16: 3 | X16: 6 | Y16: 0 | Z16: 0 | AA16: 3.5 | AB16: 0.5 | AC16: 2573 | AD16: 0.7 | AE16: 30 | AF16: 16 | AG16: 35 | AH16: 55 | AI16: 18 | AJ16: 150 | AK16: 0.3 | AL16: 0.3 | AM16: 0.2
